<?xml version="1.0"?>
<robot name="HRP5P"
       xmlns:xi="http://www.w3.org/2001/XInclude">
  <link name="Body">
    <visual>
      <origin xyz="0 0 0.862" rpy="0 -0 0"/>
      <geometry>
        <mesh filename="package://hrp5_p_description/meshes/HRP5Pmain/Body_mesh.dae" scale="1 1 1" />
      </geometry>
    </visual>
    <collision>
      <origin xyz="0 0 0.862" rpy="0 -0 0"/>
      <geometry>
        <mesh filename="package://hrp5_p_description/meshes/HRP5Pmain/Body_mesh.dae" scale="1 1 1" />
      </geometry>
    </collision>
    <inertial>
      <mass value="9.8635" />
      <origin xyz="-0.0308 0.0081 0.1756" rpy="0 -0 0"/>
      <inertia ixx="0.36871" ixy="-0.002075" ixz="-0.045841" iyy="0.407036" iyz="0.019256" izz="0.11623"/>
    </inertial>
  </link>
  <gazebo reference="Body">
    <mu1>0.9</mu1>
    <mu2>0.9</mu2>
  </gazebo>
  <link name="Lleg_Link0">
    <visual>
      <origin xyz="0 0.06 0" rpy="0 -0 0"/>
      <geometry>
        <mesh filename="package://hrp5_p_description/meshes/HRP5Pmain/Lleg_Link0_mesh.dae" scale="1 1 1" />
      </geometry>
    </visual>
    <collision>
      <origin xyz="0 0.06 0" rpy="0 -0 0"/>
      <geometry>
        <mesh filename="package://hrp5_p_description/meshes/HRP5Pmain/Lleg_Link0_mesh.dae" scale="1 1 1" />
      </geometry>
    </collision>
    <inertial>
      <mass value="2.5255" />
      <origin xyz="0.0046 0.0004 0.0779" rpy="0 -0 0"/>
      <inertia ixx="0.023207" ixy="-3.6e-05" ixz="-2.5e-05" iyy="0.023692" iyz="0.000309" izz="0.003152"/>
    </inertial>
  </link>
  <gazebo reference="Lleg_Link0">
    <mu1>0.9</mu1>
    <mu2>0.9</mu2>
  </gazebo>
  <link name="Lleg_Link1">
    <visual>
      <origin xyz="0 0 0" rpy="0 -0 0"/>
      <geometry>
        <mesh filename="package://hrp5_p_description/meshes/HRP5Pmain/Lleg_Link1_mesh.dae" scale="1 1 1" />
      </geometry>
    </visual>
    <collision>
      <origin xyz="0 0 0" rpy="0 -0 0"/>
      <geometry>
        <mesh filename="package://hrp5_p_description/meshes/HRP5Pmain/Lleg_Link1_mesh.dae" scale="1 1 1" />
      </geometry>
    </collision>
    <inertial>
      <mass value="1.4061" />
      <origin xyz="-0.0048 0.044 -0.0024" rpy="0 -0 0"/>
      <inertia ixx="0.006125" ixy="-1.3e-05" ixz="3e-05" iyy="0.000871" iyz="-8e-06" izz="0.006185"/>
    </inertial>
  </link>
  <gazebo reference="Lleg_Link1">
    <mu1>0.9</mu1>
    <mu2>0.9</mu2>
  </gazebo>
  <link name="Lleg_Link2">
    <visual>
      <origin xyz="0 0 0" rpy="0 -0 0"/>
      <geometry>
        <mesh filename="package://hrp5_p_description/meshes/HRP5Pmain/Lleg_Link2_mesh.dae" scale="1 1 1" />
      </geometry>
    </visual>
    <collision>
      <origin xyz="0 0 0" rpy="0 -0 0"/>
      <geometry>
        <mesh filename="package://hrp5_p_description/meshes/HRP5Pmain/Lleg_Link2_mesh.dae" scale="1 1 1" />
      </geometry>
    </collision>
    <inertial>
      <mass value="6.4744" />
      <origin xyz="-0.0027 0.0892 -0.1996" rpy="0 -0 0"/>
      <inertia ixx="0.437272" ixy="-0.00167" ixz="0.001713" iyy="0.381504" iyz="-0.101544" izz="0.066235"/>
    </inertial>
  </link>
  <gazebo reference="Lleg_Link2">
    <mu1>0.9</mu1>
    <mu2>0.9</mu2>
  </gazebo>
  <link name="Lleg_Link3">
    <visual>
      <origin xyz="0 0.035 -0.38" rpy="0 -0 0"/>
      <geometry>
        <mesh filename="package://hrp5_p_description/meshes/HRP5Pmain/Lleg_Link3_mesh.dae" scale="1 1 1" />
      </geometry>
    </visual>
    <collision>
      <origin xyz="0 0.035 -0.38" rpy="0 -0 0"/>
      <geometry>
        <mesh filename="package://hrp5_p_description/meshes/HRP5Pmain/Lleg_Link3_mesh.dae" scale="1 1 1" />
      </geometry>
    </collision>
    <inertial>
      <mass value="3.1903" />
      <origin xyz="0.01 0.0093 -0.1305" rpy="0 -0 0"/>
      <inertia ixx="0.108668" ixy="0.000271" ixz="-0.003711" iyy="0.107551" iyz="-0.001717" izz="0.005845"/>
    </inertial>
  </link>
  <gazebo reference="Lleg_Link3">
    <mu1>0.9</mu1>
    <mu2>0.9</mu2>
  </gazebo>
  <link name="Lleg_Link4">
    <visual>
      <origin xyz="0 0 -0.38" rpy="0 -0 0"/>
      <geometry>
        <mesh filename="package://hrp5_p_description/meshes/HRP5Pmain/Lleg_Link4_mesh.dae" scale="1 1 1" />
      </geometry>
    </visual>
    <collision>
      <origin xyz="0 0 -0.38" rpy="0 -0 0"/>
      <geometry>
        <mesh filename="package://hrp5_p_description/meshes/HRP5Pmain/Lleg_Link4_mesh.dae" scale="1 1 1" />
      </geometry>
    </collision>
    <inertial>
      <mass value="1.1568" />
      <origin xyz="-0.0131 0.0018 0.0181" rpy="0 -0 0"/>
      <inertia ixx="0.001336" ixy="-2e-06" ixz="3.5e-05" iyy="0.002759" iyz="1.4e-05" izz="0.001689"/>
    </inertial>
  </link>
  <gazebo reference="Lleg_Link4">
    <mu1>0.9</mu1>
    <mu2>0.9</mu2>
  </gazebo>
  <link name="Lleg_Link5">
    <visual>
      <origin xyz="0 0 0" rpy="0 -0 0"/>
      <geometry>
        <mesh filename="package://hrp5_p_description/meshes/HRP5Pmain/Lleg_Link5_mesh.dae" scale="1 1 1" />
      </geometry>
    </visual>
    <collision>
      <origin xyz="0 0 0" rpy="0 -0 0"/>
      <geometry>
        <mesh filename="package://hrp5_p_description/meshes/HRP5Pmain/Lleg_Link5_mesh.dae" scale="1 1 1" />
      </geometry>
    </collision>
    <inertial>
      <mass value="1.6195" />
      <origin xyz="-0.0091 0.0031 -0.0603" rpy="0 -0 0"/>
      <inertia ixx="0.008507" ixy="7.2e-05" ixz="-0.000535" iyy="0.011944" iyz="-0.000433" izz="0.006085"/>
    </inertial>
  </link>
  <gazebo reference="Lleg_Link5">
    <mu1>0.9</mu1>
    <mu2>0.9</mu2>
  </gazebo>
  <link name="Rleg_Link0">
    <visual>
      <origin xyz="0 -0.06 0" rpy="0 -0 0"/>
      <geometry>
        <mesh filename="package://hrp5_p_description/meshes/HRP5Pmain/Rleg_Link0_mesh.dae" scale="1 1 1" />
      </geometry>
    </visual>
    <collision>
      <origin xyz="0 -0.06 0" rpy="0 -0 0"/>
      <geometry>
        <mesh filename="package://hrp5_p_description/meshes/HRP5Pmain/Rleg_Link0_mesh.dae" scale="1 1 1" />
      </geometry>
    </collision>
    <inertial>
      <mass value="2.5255" />
      <origin xyz="0.0046 -0.0004 0.0779" rpy="0 -0 0"/>
      <inertia ixx="0.023207" ixy="3.6e-05" ixz="-2.5e-05" iyy="0.023692" iyz="-0.000309" izz="0.003152"/>
    </inertial>
  </link>
  <gazebo reference="Rleg_Link0">
    <mu1>0.9</mu1>
    <mu2>0.9</mu2>
  </gazebo>
  <link name="Rleg_Link1">
    <visual>
      <origin xyz="0 0 0" rpy="0 -0 0"/>
      <geometry>
        <mesh filename="package://hrp5_p_description/meshes/HRP5Pmain/Rleg_Link1_mesh.dae" scale="1 1 1" />
      </geometry>
    </visual>
    <collision>
      <origin xyz="0 0 0" rpy="0 -0 0"/>
      <geometry>
        <mesh filename="package://hrp5_p_description/meshes/HRP5Pmain/Rleg_Link1_mesh.dae" scale="1 1 1" />
      </geometry>
    </collision>
    <inertial>
      <mass value="1.4061" />
      <origin xyz="-0.0048 -0.044 -0.0024" rpy="0 -0 0"/>
      <inertia ixx="0.006125" ixy="1.3e-05" ixz="3e-05" iyy="0.000871" iyz="8e-06" izz="0.006185"/>
    </inertial>
  </link>
  <gazebo reference="Rleg_Link1">
    <mu1>0.9</mu1>
    <mu2>0.9</mu2>
  </gazebo>
  <link name="Rleg_Link2">
    <visual>
      <origin xyz="0 0 0" rpy="0 -0 0"/>
      <geometry>
        <mesh filename="package://hrp5_p_description/meshes/HRP5Pmain/Rleg_Link2_mesh.dae" scale="1 1 1" />
      </geometry>
    </visual>
    <collision>
      <origin xyz="0 0 0" rpy="0 -0 0"/>
      <geometry>
        <mesh filename="package://hrp5_p_description/meshes/HRP5Pmain/Rleg_Link2_mesh.dae" scale="1 1 1" />
      </geometry>
    </collision>
    <inertial>
      <mass value="6.4744" />
      <origin xyz="-0.0027 -0.0892 -0.1996" rpy="0 -0 0"/>
      <inertia ixx="0.437272" ixy="0.00167" ixz="0.001713" iyy="0.381504" iyz="0.101544" izz="0.066235"/>
    </inertial>
  </link>
  <gazebo reference="Rleg_Link2">
    <mu1>0.9</mu1>
    <mu2>0.9</mu2>
  </gazebo>
  <link name="Rleg_Link3">
    <visual>
      <origin xyz="0 -0.035 -0.38" rpy="0 -0 0"/>
      <geometry>
        <mesh filename="package://hrp5_p_description/meshes/HRP5Pmain/Rleg_Link3_mesh.dae" scale="1 1 1" />
      </geometry>
    </visual>
    <collision>
      <origin xyz="0 -0.035 -0.38" rpy="0 -0 0"/>
      <geometry>
        <mesh filename="package://hrp5_p_description/meshes/HRP5Pmain/Rleg_Link3_mesh.dae" scale="1 1 1" />
      </geometry>
    </collision>
    <inertial>
      <mass value="3.1903" />
      <origin xyz="0.01 -0.0093 -0.1305" rpy="0 -0 0"/>
      <inertia ixx="0.108668" ixy="-0.000271" ixz="-0.003711" iyy="0.107551" iyz="0.001717" izz="0.005845"/>
    </inertial>
  </link>
  <gazebo reference="Rleg_Link3">
    <mu1>0.9</mu1>
    <mu2>0.9</mu2>
  </gazebo>
  <link name="Rleg_Link4">
    <visual>
      <origin xyz="0 0 -0.38" rpy="0 -0 0"/>
      <geometry>
        <mesh filename="package://hrp5_p_description/meshes/HRP5Pmain/Rleg_Link4_mesh.dae" scale="1 1 1" />
      </geometry>
    </visual>
    <collision>
      <origin xyz="0 0 -0.38" rpy="0 -0 0"/>
      <geometry>
        <mesh filename="package://hrp5_p_description/meshes/HRP5Pmain/Rleg_Link4_mesh.dae" scale="1 1 1" />
      </geometry>
    </collision>
    <inertial>
      <mass value="1.1568" />
      <origin xyz="-0.0131 -0.0018 0.0181" rpy="0 -0 0"/>
      <inertia ixx="0.001336" ixy="2e-06" ixz="3.5e-05" iyy="0.002759" iyz="-1.4e-05" izz="0.001689"/>
    </inertial>
  </link>
  <gazebo reference="Rleg_Link4">
    <mu1>0.9</mu1>
    <mu2>0.9</mu2>
  </gazebo>
  <link name="Rleg_Link5">
    <visual>
      <origin xyz="0 0 0" rpy="0 -0 0"/>
      <geometry>
        <mesh filename="package://hrp5_p_description/meshes/HRP5Pmain/Rleg_Link5_mesh.dae" scale="1 1 1" />
      </geometry>
    </visual>
    <collision>
      <origin xyz="0 0 0" rpy="0 -0 0"/>
      <geometry>
        <mesh filename="package://hrp5_p_description/meshes/HRP5Pmain/Rleg_Link5_mesh.dae" scale="1 1 1" />
      </geometry>
    </collision>
    <inertial>
      <mass value="1.6195" />
      <origin xyz="-0.0091 -0.0031 -0.0603" rpy="0 -0 0"/>
      <inertia ixx="0.008507" ixy="-7.2e-05" ixz="-0.000535" iyy="0.011944" iyz="0.000433" izz="0.006085"/>
    </inertial>
  </link>
  <gazebo reference="Rleg_Link5">
    <mu1>0.9</mu1>
    <mu2>0.9</mu2>
  </gazebo>
  <link name="Chest_Link0">
    <visual>
      <origin xyz="0.055 0 0.274" rpy="0 -0 0"/>
      <geometry>
        <mesh filename="package://hrp5_p_description/meshes/HRP5Pmain/Chest_Link0_mesh.dae" scale="1 1 1" />
      </geometry>
    </visual>
    <collision>
      <origin xyz="0.055 0 0.274" rpy="0 -0 0"/>
      <geometry>
        <mesh filename="package://hrp5_p_description/meshes/HRP5Pmain/Chest_Link0_mesh.dae" scale="1 1 1" />
      </geometry>
    </collision>
    <inertial>
      <mass value="1.0948" />
      <origin xyz="-0.0279 0.0051 0" rpy="0 -0 0"/>
      <inertia ixx="0.001062" ixy="-2e-06" ixz="1e-06" iyy="0.002342" iyz="5.86165e-20" izz="0.002966"/>
    </inertial>
  </link>
  <gazebo reference="Chest_Link0">
    <mu1>0.9</mu1>
    <mu2>0.9</mu2>
  </gazebo>
  <link name="Chest_Link1">
    <visual>
      <origin xyz="0 0 0" rpy="0 -0 0"/>
      <geometry>
        <mesh filename="package://hrp5_p_description/meshes/HRP5Pmain/Chest_Link1_mesh.dae" scale="1 1 1" />
      </geometry>
    </visual>
    <collision>
      <origin xyz="0 0 0" rpy="0 -0 0"/>
      <geometry>
        <mesh filename="package://hrp5_p_description/meshes/HRP5Pmain/Chest_Link1_mesh.dae" scale="1 1 1" />
      </geometry>
    </collision>
    <inertial>
      <mass value="3.196" />
      <origin xyz="-0.0617 -0.0019 0.0601" rpy="0 -0 0"/>
      <inertia ixx="0.018231" ixy="0.000519" ixz="-0.007109" iyy="0.037917" iyz="-0.000359" izz="0.0227"/>
    </inertial>
  </link>
  <gazebo reference="Chest_Link1">
    <mu1>0.9</mu1>
    <mu2>0.9</mu2>
  </gazebo>
  <link name="Chest_Link2">
    <visual>
      <origin xyz="0 0 0" rpy="0 -0 0"/>
      <geometry>
        <mesh filename="package://hrp5_p_description/meshes/HRP5Pmain/Chest_Link2_mesh.dae" scale="1 1 1" />
      </geometry>
    </visual>
    <collision>
      <origin xyz="0 0 0" rpy="0 -0 0"/>
      <geometry>
        <mesh filename="package://hrp5_p_description/meshes/HRP5Pmain/Chest_Link2_mesh.dae" scale="1 1 1" />
      </geometry>
    </collision>
    <inertial>
      <mass value="24.4837" />
      <origin xyz="-0.145 -0.004 0.2482" rpy="0 -0 0"/>
      <inertia ixx="1.91563" ixy="0.014602" ixz="-0.653675" iyy="2.38048" iyz="-0.021382" izz="0.728339"/>
    </inertial>
  </link>
  <gazebo reference="Chest_Link2">
    <mu1>0.9</mu1>
    <mu2>0.9</mu2>
  </gazebo>
  <link name="Head_Link0">
    <visual>
      <origin xyz="0.032 0 0.549" rpy="0 -0 0"/>
      <geometry>
        <mesh filename="package://hrp5_p_description/meshes/HRP5Pmain/Head_Link0_mesh.dae" scale="1 1 1" />
      </geometry>
    </visual>
    <collision>
      <origin xyz="0.032 0 0.549" rpy="0 -0 0"/>
      <geometry>
        <mesh filename="package://hrp5_p_description/meshes/HRP5Pmain/Head_Link0_mesh.dae" scale="1 1 1" />
      </geometry>
    </collision>
    <inertial>
      <mass value="0.9321" />
      <origin xyz="0.0122 -0.0136 -0.0955" rpy="0 -0 0"/>
      <inertia ixx="0.015844" ixy="-0.000476" ixz="-4.7e-05" iyy="0.012032" iyz="-6.8e-05" izz="0.005011"/>
    </inertial>
  </link>
  <gazebo reference="Head_Link0">
    <mu1>0.9</mu1>
    <mu2>0.9</mu2>
  </gazebo>
  <link name="Head_Link1_Plan2">
    <visual>
      <origin xyz="0.04 0 0" rpy="0 -0 0"/>
      <geometry>
        <mesh filename="package://hrp5_p_description/meshes/HRP5Pmain/Head_Link1_Plan2_mesh.dae" scale="1 1 1" />
      </geometry>
    </visual>
    <collision>
      <origin xyz="0.04 0 0" rpy="0 -0 0"/>
      <geometry>
        <mesh filename="package://hrp5_p_description/meshes/HRP5Pmain/Head_Link1_Plan2_mesh.dae" scale="1 1 1" />
      </geometry>
    </collision>
    <inertial>
      <mass value="3.04836" />
      <origin xyz="0.00766 -1e-05 0.02739" rpy="0 -0 0"/>
      <inertia ixx="0.012466" ixy="2e-06" ixz="-0.002212" iyy="0.010513" iyz="3e-06" izz="0.010517"/>
    </inertial>
  </link>
  <gazebo reference="Head_Link1_Plan2">
    <mu1>0.9</mu1>
    <mu2>0.9</mu2>
  </gazebo>
  <link name="azure_depth_frame">
    <inertial>
      <mass value="0" />
      <origin xyz="8.67362e-19 -1.11022e-16 -2.77556e-17" rpy="0 -0 0"/>
      <inertia ixx="0" ixy="0" ixz="0" iyy="0" iyz="0" izz="0"/>
    </inertial>
  </link>
  <gazebo reference="azure_depth_frame">
    <mu1>0.9</mu1>
    <mu2>0.9</mu2>
  </gazebo>
  <link name="head_root">
    <inertial>
      <mass value="0" />
      <origin xyz="0 0 -2.22045e-16" rpy="0 -0 0"/>
      <inertia ixx="0" ixy="0" ixz="0" iyy="0" iyz="0" izz="0"/>
    </inertial>
  </link>
  <gazebo reference="head_root">
    <mu1>0.9</mu1>
    <mu2>0.9</mu2>
  </gazebo>
  <link name="left_camera_optical_frame">
    <inertial>
      <mass value="0" />
      <origin xyz="-2.08167e-17 3.33067e-16 0" rpy="0 -0 0"/>
      <inertia ixx="0" ixy="0" ixz="0" iyy="0" iyz="0" izz="0"/>
    </inertial>
  </link>
  <gazebo reference="left_camera_optical_frame">
    <mu1>0.9</mu1>
    <mu2>0.9</mu2>
  </gazebo>
  <link name="motor">
    <inertial>
      <mass value="0" />
      <origin xyz="1.66533e-16 3.33067e-16 0" rpy="0 -0 0"/>
      <inertia ixx="0" ixy="0" ixz="0" iyy="0" iyz="0" izz="0"/>
    </inertial>
  </link>
  <gazebo reference="motor">
    <mu1>0.9</mu1>
    <mu2>0.9</mu2>
  </gazebo>
  <link name="spindle">
    <visual>
      <origin xyz="0 0 0" rpy="0 -0 0"/>
      <geometry>
        <mesh filename="package://hrp5_p_description/meshes/HRP5Pmain/spindle_mesh.dae" scale="1 1 1" />
      </geometry>
    </visual>
    <collision>
      <origin xyz="0 0 0" rpy="0 -0 0"/>
      <geometry>
        <mesh filename="package://hrp5_p_description/meshes/HRP5Pmain/spindle_mesh.dae" scale="1 1 1" />
      </geometry>
    </collision>
    <inertial>
      <mass value="0.45853" />
      <origin xyz="-7.17653e-08 0.00395994 0.02142" rpy="0 -0 0"/>
      <inertia ixx="1" ixy="-1.0581e-16" ixz="1.16254e-16" iyy="1" iyz="-5.55112e-17" izz="1"/>
    </inertial>
  </link>
  <gazebo reference="spindle">
    <mu1>0.9</mu1>
    <mu2>0.9</mu2>
  </gazebo>
  <link name="hokuyo_link">
    <inertial>
      <mass value="0" />
      <origin xyz="2.77556e-17 1.66533e-16 2.22045e-16" rpy="0 -0 0"/>
      <inertia ixx="0" ixy="0" ixz="0" iyy="0" iyz="0" izz="0"/>
    </inertial>
  </link>
  <gazebo reference="hokuyo_link">
    <mu1>0.9</mu1>
    <mu2>0.9</mu2>
  </gazebo>
  <link name="head_hokuyo_frame">
    <inertial>
      <mass value="0" />
      <origin xyz="3.33067e-16 0 1.11022e-16" rpy="0 -0 0"/>
      <inertia ixx="0" ixy="0" ixz="0" iyy="0" iyz="0" izz="0"/>
    </inertial>
  </link>
  <gazebo reference="head_hokuyo_frame">
    <mu1>0.9</mu1>
    <mu2>0.9</mu2>
  </gazebo>
  <link name="right_camera_optical_frame">
    <inertial>
      <mass value="0" />
      <origin xyz="1.38778e-17 1.11022e-16 0" rpy="0 -0 0"/>
      <inertia ixx="0" ixy="0" ixz="0" iyy="0" iyz="0" izz="0"/>
    </inertial>
  </link>
  <gazebo reference="right_camera_optical_frame">
    <mu1>0.9</mu1>
    <mu2>0.9</mu2>
  </gazebo>
  <link name="realsense_link">
    <inertial>
      <mass value="0" />
      <origin xyz="0 0 0" rpy="0 -0 0"/>
      <inertia ixx="0" ixy="0" ixz="0" iyy="0" iyz="0" izz="0"/>
    </inertial>
  </link>
  <gazebo reference="realsense_link">
    <mu1>0.9</mu1>
    <mu2>0.9</mu2>
  </gazebo>
  <link name="realsense_aligned_depth_to_color_frame">
    <inertial>
      <mass value="0" />
      <origin xyz="0 0 0" rpy="0 -0 0"/>
      <inertia ixx="0" ixy="0" ixz="0" iyy="0" iyz="0" izz="0"/>
    </inertial>
  </link>
  <gazebo reference="realsense_aligned_depth_to_color_frame">
    <mu1>0.9</mu1>
    <mu2>0.9</mu2>
  </gazebo>
  <link name="realsense_color_optical_frame">
    <inertial>
      <mass value="0" />
      <origin xyz="0 0 0" rpy="0 -0 0"/>
      <inertia ixx="0" ixy="0" ixz="0" iyy="0" iyz="0" izz="0"/>
    </inertial>
  </link>
  <gazebo reference="realsense_color_optical_frame">
    <mu1>0.9</mu1>
    <mu2>0.9</mu2>
  </gazebo>
  <link name="realsense_color_frame">
    <inertial>
      <mass value="0" />
      <origin xyz="0 0 0" rpy="0 -0 0"/>
      <inertia ixx="0" ixy="0" ixz="0" iyy="0" iyz="0" izz="0"/>
    </inertial>
  </link>
  <gazebo reference="realsense_color_frame">
    <mu1>0.9</mu1>
    <mu2>0.9</mu2>
  </gazebo>
  <link name="realsense_depth_frame">
    <inertial>
      <mass value="0" />
      <origin xyz="0 0 0" rpy="0 -0 0"/>
      <inertia ixx="0" ixy="0" ixz="0" iyy="0" iyz="0" izz="0"/>
    </inertial>
  </link>
  <gazebo reference="realsense_depth_frame">
    <mu1>0.9</mu1>
    <mu2>0.9</mu2>
  </gazebo>
  <link name="realsense_depth_optical_frame">
    <inertial>
      <mass value="0" />
      <origin xyz="0 0 0" rpy="0 -0 0"/>
      <inertia ixx="0" ixy="0" ixz="0" iyy="0" iyz="0" izz="0"/>
    </inertial>
  </link>
  <gazebo reference="realsense_depth_optical_frame">
    <mu1>0.9</mu1>
    <mu2>0.9</mu2>
  </gazebo>
  <link name="Lscap_Link0">
    <visual>
      <origin xyz="0.032 0.08 0.268" rpy="0 -0 0"/>
      <geometry>
        <mesh filename="package://hrp5_p_description/meshes/HRP5Pmain/Lscap_Link0_mesh.dae" scale="1 1 1" />
      </geometry>
    </visual>
    <collision>
      <origin xyz="0.032 0.08 0.268" rpy="0 -0 0"/>
      <geometry>
        <mesh filename="package://hrp5_p_description/meshes/HRP5Pmain/Lscap_Link0_mesh.dae" scale="1 1 1" />
      </geometry>
    </collision>
    <inertial>
      <mass value="1.7614" />
      <origin xyz="0.0054 -0.0004 -0.0061" rpy="0 -0 0"/>
      <inertia ixx="0.004959" ixy="0.000111" ixz="0.000458" iyy="0.005139" iyz="0.000191" izz="0.001461"/>
    </inertial>
  </link>
  <gazebo reference="Lscap_Link0">
    <mu1>0.9</mu1>
    <mu2>0.9</mu2>
  </gazebo>
  <link name="Larm_Link0">
    <visual>
      <origin xyz="0 0.13 0" rpy="0 -0 0"/>
      <geometry>
        <mesh filename="package://hrp5_p_description/meshes/HRP5Pmain/Larm_Link0_mesh.dae" scale="1 1 1" />
      </geometry>
    </visual>
    <collision>
      <origin xyz="0 0.13 0" rpy="0 -0 0"/>
      <geometry>
        <mesh filename="package://hrp5_p_description/meshes/HRP5Pmain/Larm_Link0_mesh.dae" scale="1 1 1" />
      </geometry>
    </collision>
    <inertial>
      <mass value="1.5836" />
      <origin xyz="0.0237 -0.0443 0.0036" rpy="0 -0 0"/>
      <inertia ixx="0.007218" ixy="-0.000284" ixz="0.000131" iyy="0.004649" iyz="-0.000198" izz="0.009889"/>
    </inertial>
  </link>
  <gazebo reference="Larm_Link0">
    <mu1>0.9</mu1>
    <mu2>0.9</mu2>
  </gazebo>
  <link name="Larm_Link1">
    <visual>
      <origin xyz="0 0 0" rpy="0 -0 0"/>
      <geometry>
        <mesh filename="package://hrp5_p_description/meshes/HRP5Pmain/Larm_Link1_mesh.dae" scale="1 1 1" />
      </geometry>
    </visual>
    <collision>
      <origin xyz="0 0 0" rpy="0 -0 0"/>
      <geometry>
        <mesh filename="package://hrp5_p_description/meshes/HRP5Pmain/Larm_Link1_mesh.dae" scale="1 1 1" />
      </geometry>
    </collision>
    <inertial>
      <mass value="1.4994" />
      <origin xyz="0.0107 0.021 -0.0227" rpy="0 -0 0"/>
      <inertia ixx="0.003445" ixy="-0.000281" ixz="0.000103" iyy="0.003747" iyz="-0.000881" izz="0.003448"/>
    </inertial>
  </link>
  <gazebo reference="Larm_Link1">
    <mu1>0.9</mu1>
    <mu2>0.9</mu2>
  </gazebo>
  <link name="Larm_Link2">
    <visual>
      <origin xyz="0 0.02 0" rpy="0 -0 0"/>
      <geometry>
        <mesh filename="package://hrp5_p_description/meshes/HRP5Pmain/Larm_Link2_mesh.dae" scale="1 1 1" />
      </geometry>
    </visual>
    <collision>
      <origin xyz="0 0.02 0" rpy="0 -0 0"/>
      <geometry>
        <mesh filename="package://hrp5_p_description/meshes/HRP5Pmain/Larm_Link2_mesh.dae" scale="1 1 1" />
      </geometry>
    </collision>
    <inertial>
      <mass value="3.127" />
      <origin xyz="0.0027 -0.0082 -0.1873" rpy="0 -0 0"/>
      <inertia ixx="0.130841" ixy="-0.000863" ixz="-0.004922" iyy="0.131689" iyz="0.00703" izz="0.0058"/>
    </inertial>
  </link>
  <gazebo reference="Larm_Link2">
    <mu1>0.9</mu1>
    <mu2>0.9</mu2>
  </gazebo>
  <link name="Larm_Link3">
    <visual>
      <origin xyz="0.05 0 -0.295804" rpy="0 -0 0"/>
      <geometry>
        <mesh filename="package://hrp5_p_description/meshes/HRP5Pmain/Larm_Link3_mesh.dae" scale="1 1 1" />
      </geometry>
    </visual>
    <collision>
      <origin xyz="0.05 0 -0.295804" rpy="0 -0 0"/>
      <geometry>
        <mesh filename="package://hrp5_p_description/meshes/HRP5Pmain/Larm_Link3_mesh.dae" scale="1 1 1" />
      </geometry>
    </collision>
    <inertial>
      <mass value="1.5959" />
      <origin xyz="-0.0348 0.0052 -0.0405" rpy="0 -0 0"/>
      <inertia ixx="0.005911" ixy="-0.000242" ixz="0.002972" iyy="0.00792" iyz="-8.5e-05" izz="0.004008"/>
    </inertial>
  </link>
  <gazebo reference="Larm_Link3">
    <mu1>0.9</mu1>
    <mu2>0.9</mu2>
  </gazebo>
  <link name="Larm_Link4">
    <visual>
      <origin xyz="-0.05 0 -0.295804" rpy="0 -0 0"/>
      <geometry>
        <mesh filename="package://hrp5_p_description/meshes/HRP5Pmain/Larm_Link4_mesh.dae" scale="1 1 1" />
      </geometry>
    </visual>
    <collision>
      <origin xyz="-0.05 0 -0.295804" rpy="0 -0 0"/>
      <geometry>
        <mesh filename="package://hrp5_p_description/meshes/HRP5Pmain/Larm_Link4_mesh.dae" scale="1 1 1" />
      </geometry>
    </collision>
    <inertial>
      <mass value="1.9223" />
      <origin xyz="-0.0154 0.0001 0.112" rpy="0 -0 0"/>
      <inertia ixx="0.032413" ixy="-3.9e-05" ixz="-0.002154" iyy="0.033673" iyz="1.2e-05" izz="0.002986"/>
    </inertial>
  </link>
  <gazebo reference="Larm_Link4">
    <mu1>0.9</mu1>
    <mu2>0.9</mu2>
  </gazebo>
  <link name="Larm_Link5">
    <visual>
      <origin xyz="0 0 0" rpy="0 -0 0"/>
      <geometry>
        <mesh filename="package://hrp5_p_description/meshes/HRP5Pmain/Larm_Link5_mesh.dae" scale="1 1 1" />
      </geometry>
    </visual>
    <collision>
      <origin xyz="0 0 0" rpy="0 -0 0"/>
      <geometry>
        <mesh filename="package://hrp5_p_description/meshes/HRP5Pmain/Larm_Link5_mesh.dae" scale="1 1 1" />
      </geometry>
    </collision>
    <inertial>
      <mass value="0.3476" />
      <origin xyz="-0.0019 0.0108 -0.0011" rpy="0 -0 0"/>
      <inertia ixx="0.000189" ixy="3.33043e-21" ixz="-3.06817e-20" iyy="0.000135" iyz="-6e-06" izz="0.000258"/>
    </inertial>
  </link>
  <gazebo reference="Larm_Link5">
    <mu1>0.9</mu1>
    <mu2>0.9</mu2>
  </gazebo>
  <link name="Larm_Link6">
    <visual>
      <origin xyz="0 0 0" rpy="0 -0 0"/>
      <geometry>
        <mesh filename="package://hrp5_p_description/meshes/HRP5Pmain/Larm_Link6_mesh.dae" scale="1 1 1" />
      </geometry>
    </visual>
    <collision>
      <origin xyz="0 0 0" rpy="0 -0 0"/>
      <geometry>
        <mesh filename="package://hrp5_p_description/meshes/HRP5Pmain/Larm_Link6_mesh.dae" scale="1 1 1" />
      </geometry>
    </collision>
    <inertial>
      <mass value="0.858" />
      <origin xyz="0.0002 0.0028 -0.052" rpy="0 -0 0"/>
      <inertia ixx="0.004772" ixy="-1e-06" ixz="-8e-06" iyy="0.003715" iyz="0.000831" izz="0.001362"/>
    </inertial>
  </link>
  <gazebo reference="Larm_Link6">
    <mu1>0.9</mu1>
    <mu2>0.9</mu2>
  </gazebo>
  <link name="Lhand_Link0_Plan2">
    <visual>
      <origin xyz="0 -0.017324 -0.078842" rpy="-0.785398 0 0"/>
      <geometry>
        <mesh filename="package://hrp5_p_description/meshes/HRP5Pmain/Lhand_Link0_Plan2_mesh.dae" scale="1 1 1" />
      </geometry>
    </visual>
    <collision>
      <origin xyz="0 -0.017324 -0.078842" rpy="-0.785398 0 0"/>
      <geometry>
        <mesh filename="package://hrp5_p_description/meshes/HRP5Pmain/Lhand_Link0_Plan2_mesh.dae" scale="1 1 1" />
      </geometry>
    </collision>
    <inertial>
      <mass value="1.505" />
      <origin xyz="-0.0019 0.0022 -0.0732" rpy="0 -0 0"/>
      <inertia ixx="0.010557" ixy="-8.7e-05" ixz="0.000334" iyy="0.009854" iyz="-0.000173" izz="0.003151"/>
    </inertial>
  </link>
  <gazebo reference="Lhand_Link0_Plan2">
    <mu1>0.9</mu1>
    <mu2>0.9</mu2>
  </gazebo>

  <link name="Hammer">
    <visual>
      <origin xyz="0 -0.024 0" rpy="0 1.57 0"/>
      <geometry>
        <mesh filename="/home/helene/workspace/sandbox/hrp5p_mj_description/meshes/visual/hammer_scaled.stl" scale="1 1 1" />
      </geometry>
    </visual>
    <collision>
      <origin xyz="0 -0.024 0" rpy="0 1.57 0"/>
      <geometry>
        <mesh filename="/home/helene/workspace/sandbox/hrp5p_mj_description/meshes/visual/hammer_scaled.stl" scale="1 1 1" />
      </geometry>
    </collision>
    <inertial>
      <mass value="0.792" />
      <origin xyz="0.177584 -0.002853 0.511187" rpy="0 1.57 3.14"/>
      <inertia ixx="0.005283" ixy="0.000000" ixz="-0.005278" iyy="0.197739" iyz="-0.000000" izz="0.193665"/>
    </inertial>
  </link>

  <link name="Hammer_Head">
    <visual>
      <origin xyz="0.17 0.01 0.21" rpy="1.57 0.0 0.0"/>
    </visual>
    <collision>
      <origin xyz="0.17 0.01 0.21" rpy="1.57 0.0 0.0"/>
    </collision>
  </link>  

  <link name="Lindex_Link0">
    <visual>
      <origin xyz="0.03 0.047 -0.114" rpy="3.14159 -0 0"/>
      <geometry>
        <mesh filename="package://hrp5_p_description/meshes/HRP5Pmain/Lindex_Link0_mesh.dae" scale="1 1 1" />
      </geometry>
    </visual>
    <collision>
      <origin xyz="0.03 0.047 -0.114" rpy="3.14159 -0 0"/>
      <geometry>
        <mesh filename="package://hrp5_p_description/meshes/HRP5Pmain/Lindex_Link0_mesh.dae" scale="1 1 1" />
      </geometry>
    </collision>
    <inertial>
      <mass value="0.0495" />
      <origin xyz="0 0.0249 0.0047" rpy="0 -0 0"/>
      <inertia ixx="4.9e-05" ixy="-3.56804e-21" ixz="-2.42283e-22" iyy="7e-06" iyz="6e-06" izz="4.7e-05"/>
    </inertial>
  </link>
  <gazebo reference="Lindex_Link0">
    <mu1>0.9</mu1>
    <mu2>0.9</mu2>
  </gazebo>
  <link name="Lindex_Link1">
    <visual>
      <origin xyz="0 0.046 0" rpy="0 -0 0"/>
      <geometry>
        <mesh filename="package://hrp5_p_description/meshes/HRP5Pmain/Lindex_Link1_mesh.dae" scale="1 1 1" />
      </geometry>
    </visual>
    <collision>
      <origin xyz="0 0.046 0" rpy="0 -0 0"/>
      <geometry>
        <mesh filename="package://hrp5_p_description/meshes/HRP5Pmain/Lindex_Link1_mesh.dae" scale="1 1 1" />
      </geometry>
    </collision>
    <inertial>
      <mass value="0.023" />
      <origin xyz="0 0.0172 0.0027" rpy="0 -0 0"/>
      <inertia ixx="1e-05" ixy="-2.82315e-22" ixz="-7.95631e-24" iyy="2e-06" iyz="1e-06" izz="1e-05"/>
    </inertial>
  </link>
  <gazebo reference="Lindex_Link1">
    <mu1>0.9</mu1>
    <mu2>0.9</mu2>
  </gazebo>
  <link name="Lindex_Link2">
    <visual>
      <origin xyz="0 0.027 0" rpy="0 -0 0"/>
      <geometry>
        <mesh filename="package://hrp5_p_description/meshes/HRP5Pmain/Lindex_Link2_mesh.dae" scale="1 1 1" />
      </geometry>
    </visual>
    <collision>
      <origin xyz="0 0.027 0" rpy="0 -0 0"/>
      <geometry>
        <mesh filename="package://hrp5_p_description/meshes/HRP5Pmain/Lindex_Link2_mesh.dae" scale="1 1 1" />
      </geometry>
    </collision>
    <inertial>
      <mass value="0.0137" />
      <origin xyz="0 0.0119 0.0072" rpy="0 -0 0"/>
      <inertia ixx="4e-06" ixy="-7.57715e-22" ixz="5.74055e-22" iyy="2e-06" iyz="1e-06" izz="3e-06"/>
    </inertial>
  </link>
  <gazebo reference="Lindex_Link2">
    <mu1>0.9</mu1>
    <mu2>0.9</mu2>
  </gazebo>
  <link name="Lmiddle_Link0">
    <visual>
      <origin xyz="-0.03 0.047 -0.114" rpy="3.14159 -0 0"/>
      <geometry>
        <mesh filename="package://hrp5_p_description/meshes/HRP5Pmain/Lmiddle_Link0_mesh.dae" scale="1 1 1" />
      </geometry>
    </visual>
    <collision>
      <origin xyz="-0.03 0.047 -0.114" rpy="3.14159 -0 0"/>
      <geometry>
        <mesh filename="package://hrp5_p_description/meshes/HRP5Pmain/Lmiddle_Link0_mesh.dae" scale="1 1 1" />
      </geometry>
    </collision>
    <inertial>
      <mass value="0.0736" />
      <origin xyz="-0.0001 0.0151 0.0023" rpy="0 -0 0"/>
      <inertia ixx="5.3e-05" ixy="-3.78707e-21" ixz="-4.86833e-22" iyy="9e-06" iyz="6e-06" izz="4.9e-05"/>
    </inertial>
  </link>
  <gazebo reference="Lmiddle_Link0">
    <mu1>0.9</mu1>
    <mu2>0.9</mu2>
  </gazebo>
  <link name="Lmiddle_Link1">
    <visual>
      <origin xyz="0 0.046 0" rpy="0 -0 0"/>
      <geometry>
        <mesh filename="package://hrp5_p_description/meshes/HRP5Pmain/Lmiddle_Link1_mesh.dae" scale="1 1 1" />
      </geometry>
    </visual>
    <collision>
      <origin xyz="0 0.046 0" rpy="0 -0 0"/>
      <geometry>
        <mesh filename="package://hrp5_p_description/meshes/HRP5Pmain/Lmiddle_Link1_mesh.dae" scale="1 1 1" />
      </geometry>
    </collision>
    <inertial>
      <mass value="0.023" />
      <origin xyz="0 0.0172 0.0027" rpy="0 -0 0"/>
      <inertia ixx="1e-05" ixy="-2.82315e-22" ixz="-7.95631e-24" iyy="2e-06" iyz="1e-06" izz="1e-05"/>
    </inertial>
  </link>
  <gazebo reference="Lmiddle_Link1">
    <mu1>0.9</mu1>
    <mu2>0.9</mu2>
  </gazebo>
  <link name="Lmiddle_Link2">
    <visual>
      <origin xyz="0 0.027 0" rpy="0 -0 0"/>
      <geometry>
        <mesh filename="package://hrp5_p_description/meshes/HRP5Pmain/Lmiddle_Link2_mesh.dae" scale="1 1 1" />
      </geometry>
    </visual>
    <collision>
      <origin xyz="0 0.027 0" rpy="0 -0 0"/>
      <geometry>
        <mesh filename="package://hrp5_p_description/meshes/HRP5Pmain/Lmiddle_Link2_mesh.dae" scale="1 1 1" />
      </geometry>
    </collision>
    <inertial>
      <mass value="0.0137" />
      <origin xyz="0 0.0119 0.0072" rpy="0 -0 0"/>
      <inertia ixx="4e-06" ixy="-7.57715e-22" ixz="5.74055e-22" iyy="2e-06" iyz="1e-06" izz="3e-06"/>
    </inertial>
  </link>
  <gazebo reference="Lmiddle_Link2">
    <mu1>0.9</mu1>
    <mu2>0.9</mu2>
  </gazebo>
  <link name="Lthumb_Link0">
    <visual>
      <origin xyz="0 -0.047 -0.114" rpy="-3.14159 -0 0"/>
      <geometry>
        <mesh filename="package://hrp5_p_description/meshes/HRP5Pmain/Lthumb_Link0_mesh.dae" scale="1 1 1" />
      </geometry>
    </visual>
    <collision>
      <origin xyz="0 -0.047 -0.114" rpy="-3.14159 -0 0"/>
      <geometry>
        <mesh filename="package://hrp5_p_description/meshes/HRP5Pmain/Lthumb_Link0_mesh.dae" scale="1 1 1" />
      </geometry>
    </collision>
    <inertial>
      <mass value="0.0732" />
      <origin xyz="0 -0.0152 0.0023" rpy="0 -0 0"/>
      <inertia ixx="5.3e-05" ixy="4.28374e-23" ixz="-3.88658e-22" iyy="9e-06" iyz="-6e-06" izz="4.9e-05"/>
    </inertial>
  </link>
  <gazebo reference="Lthumb_Link0">
    <mu1>0.9</mu1>
    <mu2>0.9</mu2>
  </gazebo>
  <link name="Lthumb_Link1">
    <visual>
      <origin xyz="0 -0.046 0" rpy="0 -0 0"/>
      <geometry>
        <mesh filename="package://hrp5_p_description/meshes/HRP5Pmain/Lthumb_Link1_mesh.dae" scale="1 1 1" />
      </geometry>
    </visual>
    <collision>
      <origin xyz="0 -0.046 0" rpy="0 -0 0"/>
      <geometry>
        <mesh filename="package://hrp5_p_description/meshes/HRP5Pmain/Lthumb_Link1_mesh.dae" scale="1 1 1" />
      </geometry>
    </collision>
    <inertial>
      <mass value="0.023" />
      <origin xyz="0 -0.0172 0.0027" rpy="0 -0 0"/>
      <inertia ixx="1e-05" ixy="8.00493e-22" ixz="-3.118e-23" iyy="2e-06" iyz="-1e-06" izz="1e-05"/>
    </inertial>
  </link>
  <gazebo reference="Lthumb_Link1">
    <mu1>0.9</mu1>
    <mu2>0.9</mu2>
  </gazebo>
  <link name="Lthumb_Link2">
    <visual>
      <origin xyz="0 -0.027 0" rpy="0 -0 0"/>
      <geometry>
        <mesh filename="package://hrp5_p_description/meshes/HRP5Pmain/Lthumb_Link2_mesh.dae" scale="1 1 1" />
      </geometry>
    </visual>
    <collision>
      <origin xyz="0 -0.027 0" rpy="0 -0 0"/>
      <geometry>
        <mesh filename="package://hrp5_p_description/meshes/HRP5Pmain/Lthumb_Link2_mesh.dae" scale="1 1 1" />
      </geometry>
    </collision>
    <inertial>
      <mass value="0.0137" />
      <origin xyz="0 -0.0119 0.0072" rpy="0 -0 0"/>
      <inertia ixx="4e-06" ixy="1.35052e-22" ixz="1.64464e-22" iyy="2e-06" iyz="-1e-06" izz="3e-06"/>
    </inertial>
  </link>
  <gazebo reference="Lthumb_Link2">
    <mu1>0.9</mu1>
    <mu2>0.9</mu2>
  </gazebo>
  <link name="Rscap_Link0">
    <visual>
      <origin xyz="0.032 -0.08 0.268" rpy="0 -0 0"/>
      <geometry>
        <mesh filename="package://hrp5_p_description/meshes/HRP5Pmain/Rscap_Link0_mesh.dae" scale="1 1 1" />
      </geometry>
    </visual>
    <collision>
      <origin xyz="0.032 -0.08 0.268" rpy="0 -0 0"/>
      <geometry>
        <mesh filename="package://hrp5_p_description/meshes/HRP5Pmain/Rscap_Link0_mesh.dae" scale="1 1 1" />
      </geometry>
    </collision>
    <inertial>
      <mass value="1.7614" />
      <origin xyz="0.0054 0.0004 -0.0061" rpy="0 -0 0"/>
      <inertia ixx="0.004959" ixy="-0.000111" ixz="0.000458" iyy="0.005139" iyz="-0.000191" izz="0.001461"/>
    </inertial>
  </link>
  <gazebo reference="Rscap_Link0">
    <mu1>0.9</mu1>
    <mu2>0.9</mu2>
  </gazebo>
  <link name="Rarm_Link0">
    <visual>
      <origin xyz="0 -0.13 0" rpy="0 -0 0"/>
      <geometry>
        <mesh filename="package://hrp5_p_description/meshes/HRP5Pmain/Rarm_Link0_mesh.dae" scale="1 1 1" />
      </geometry>
    </visual>
    <collision>
      <origin xyz="0 -0.13 0" rpy="0 -0 0"/>
      <geometry>
        <mesh filename="package://hrp5_p_description/meshes/HRP5Pmain/Rarm_Link0_mesh.dae" scale="1 1 1" />
      </geometry>
    </collision>
    <inertial>
      <mass value="1.5836" />
      <origin xyz="0.0237 0.0443 0.0036" rpy="0 -0 0"/>
      <inertia ixx="0.007218" ixy="0.000284" ixz="0.000131" iyy="0.004649" iyz="0.000198" izz="0.009889"/>
    </inertial>
  </link>
  <gazebo reference="Rarm_Link0">
    <mu1>0.9</mu1>
    <mu2>0.9</mu2>
  </gazebo>
  <link name="Rarm_Link1">
    <visual>
      <origin xyz="0 0 0" rpy="0 -0 0"/>
      <geometry>
        <mesh filename="package://hrp5_p_description/meshes/HRP5Pmain/Rarm_Link1_mesh.dae" scale="1 1 1" />
      </geometry>
    </visual>
    <collision>
      <origin xyz="0 0 0" rpy="0 -0 0"/>
      <geometry>
        <mesh filename="package://hrp5_p_description/meshes/HRP5Pmain/Rarm_Link1_mesh.dae" scale="1 1 1" />
      </geometry>
    </collision>
    <inertial>
      <mass value="1.4994" />
      <origin xyz="0.0107 -0.021 -0.0227" rpy="0 -0 0"/>
      <inertia ixx="0.003445" ixy="0.000281" ixz="0.000103" iyy="0.003747" iyz="0.000881" izz="0.003448"/>
    </inertial>
  </link>
  <gazebo reference="Rarm_Link1">
    <mu1>0.9</mu1>
    <mu2>0.9</mu2>
  </gazebo>
  <link name="Rarm_Link2">
    <visual>
      <origin xyz="0 -0.02 0" rpy="0 -0 0"/>
      <geometry>
        <mesh filename="package://hrp5_p_description/meshes/HRP5Pmain/Rarm_Link2_mesh.dae" scale="1 1 1" />
      </geometry>
    </visual>
    <collision>
      <origin xyz="0 -0.02 0" rpy="0 -0 0"/>
      <geometry>
        <mesh filename="package://hrp5_p_description/meshes/HRP5Pmain/Rarm_Link2_mesh.dae" scale="1 1 1" />
      </geometry>
    </collision>
    <inertial>
      <mass value="3.127" />
      <origin xyz="0.0027 0.0082 -0.1873" rpy="0 -0 0"/>
      <inertia ixx="0.130841" ixy="0.000863" ixz="-0.004922" iyy="0.131689" iyz="-0.00703" izz="0.0058"/>
    </inertial>
  </link>
  <gazebo reference="Rarm_Link2">
    <mu1>0.9</mu1>
    <mu2>0.9</mu2>
  </gazebo>
  <link name="Rarm_Link3">
    <visual>
      <origin xyz="0.05 0 -0.295804" rpy="0 -0 0"/>
      <geometry>
        <mesh filename="package://hrp5_p_description/meshes/HRP5Pmain/Rarm_Link3_mesh.dae" scale="1 1 1" />
      </geometry>
    </visual>
    <collision>
      <origin xyz="0.05 0 -0.295804" rpy="0 -0 0"/>
      <geometry>
        <mesh filename="package://hrp5_p_description/meshes/HRP5Pmain/Rarm_Link3_mesh.dae" scale="1 1 1" />
      </geometry>
    </collision>
    <inertial>
      <mass value="1.5959" />
      <origin xyz="-0.0348 -0.0052 -0.0405" rpy="0 -0 0"/>
      <inertia ixx="0.005911" ixy="0.000242" ixz="0.002972" iyy="0.00792" iyz="8.5e-05" izz="0.004008"/>
    </inertial>
  </link>
  <gazebo reference="Rarm_Link3">
    <mu1>0.9</mu1>
    <mu2>0.9</mu2>
  </gazebo>
  <link name="Rarm_Link4">
    <visual>
      <origin xyz="-0.05 0 -0.295804" rpy="0 -0 0"/>
      <geometry>
        <mesh filename="package://hrp5_p_description/meshes/HRP5Pmain/Rarm_Link4_mesh.dae" scale="1 1 1" />
      </geometry>
    </visual>
    <collision>
      <origin xyz="-0.05 0 -0.295804" rpy="0 -0 0"/>
      <geometry>
        <mesh filename="package://hrp5_p_description/meshes/HRP5Pmain/Rarm_Link4_mesh.dae" scale="1 1 1" />
      </geometry>
    </collision>
    <inertial>
      <mass value="1.9223" />
      <origin xyz="-0.0154 -0.0001 0.112" rpy="0 -0 0"/>
      <inertia ixx="0.032413" ixy="3.9e-05" ixz="-0.002154" iyy="0.033673" iyz="-1.2e-05" izz="0.002986"/>
    </inertial>
  </link>
  <gazebo reference="Rarm_Link4">
    <mu1>0.9</mu1>
    <mu2>0.9</mu2>
  </gazebo>
  <link name="Rarm_Link5">
    <visual>
      <origin xyz="0 0 0" rpy="0 -0 0"/>
      <geometry>
        <mesh filename="package://hrp5_p_description/meshes/HRP5Pmain/Rarm_Link5_mesh.dae" scale="1 1 1" />
      </geometry>
    </visual>
    <collision>
      <origin xyz="0 0 0" rpy="0 -0 0"/>
      <geometry>
        <mesh filename="package://hrp5_p_description/meshes/HRP5Pmain/Rarm_Link5_mesh.dae" scale="1 1 1" />
      </geometry>
    </collision>
    <inertial>
      <mass value="0.3476" />
      <origin xyz="-0.0019 -0.0108 -0.0011" rpy="0 -0 0"/>
      <inertia ixx="0.000189" ixy="-3.33043e-21" ixz="-3.06817e-20" iyy="0.000135" iyz="6e-06" izz="0.000258"/>
    </inertial>
  </link>
  <gazebo reference="Rarm_Link5">
    <mu1>0.9</mu1>
    <mu2>0.9</mu2>
  </gazebo>
  <link name="Rarm_Link6">
    <visual>
      <origin xyz="0 0 0" rpy="0 -0 0"/>
      <geometry>
        <mesh filename="package://hrp5_p_description/meshes/HRP5Pmain/Rarm_Link6_mesh.dae" scale="1 1 1" />
      </geometry>
    </visual>
    <collision>
      <origin xyz="0 0 0" rpy="0 -0 0"/>
      <geometry>
        <mesh filename="package://hrp5_p_description/meshes/HRP5Pmain/Rarm_Link6_mesh.dae" scale="1 1 1" />
      </geometry>
    </collision>
    <inertial>
      <mass value="0.858" />
      <origin xyz="0.0002 -0.0028 -0.052" rpy="0 -0 0"/>
      <inertia ixx="0.004772" ixy="1e-06" ixz="-8e-06" iyy="0.003715" iyz="-0.000831" izz="0.001362"/>
    </inertial>
  </link>
  <gazebo reference="Rarm_Link6">
    <mu1>0.9</mu1>
    <mu2>0.9</mu2>
  </gazebo>
  <link name="Rhand_Link0_Plan2">
    <visual>
      <origin xyz="0 0.017324 -0.078842" rpy="0.785398 -0 0"/>
      <geometry>
        <mesh filename="package://hrp5_p_description/meshes/HRP5Pmain/Rhand_Link0_Plan2_mesh.dae" scale="1 1 1" />
      </geometry>
    </visual>
    <collision>
      <origin xyz="0 0.017324 -0.078842" rpy="0.785398 -0 0"/>
      <geometry>
        <mesh filename="package://hrp5_p_description/meshes/HRP5Pmain/Rhand_Link0_Plan2_mesh.dae" scale="1 1 1" />
      </geometry>
    </collision>
    <inertial>
      <mass value="1.505" />
      <origin xyz="-0.0019 -0.0022 -0.0732" rpy="0 -0 0"/>
      <inertia ixx="0.010557" ixy="8.7e-05" ixz="0.000334" iyy="0.009854" iyz="0.000173" izz="0.003151"/>
    </inertial>
  </link>
  <gazebo reference="Rhand_Link0_Plan2">
    <mu1>0.9</mu1>
    <mu2>0.9</mu2>
  </gazebo>
  <link name="Rindex_Link0">
    <visual>
      <origin xyz="0.03 -0.047 -0.114" rpy="-3.14159 -0 0"/>
      <geometry>
        <mesh filename="package://hrp5_p_description/meshes/HRP5Pmain/Rindex_Link0_mesh.dae" scale="1 1 1" />
      </geometry>
    </visual>
    <collision>
      <origin xyz="0.03 -0.047 -0.114" rpy="-3.14159 -0 0"/>
      <geometry>
        <mesh filename="package://hrp5_p_description/meshes/HRP5Pmain/Rindex_Link0_mesh.dae" scale="1 1 1" />
      </geometry>
    </collision>
    <inertial>
      <mass value="0.0495" />
      <origin xyz="0 -0.0249 0.0047" rpy="0 -0 0"/>
      <inertia ixx="4.9e-05" ixy="3.56804e-21" ixz="-2.42283e-22" iyy="7e-06" iyz="-6e-06" izz="4.7e-05"/>
    </inertial>
  </link>
  <gazebo reference="Rindex_Link0">
    <mu1>0.9</mu1>
    <mu2>0.9</mu2>
  </gazebo>
  <link name="Rindex_Link1">
    <visual>
      <origin xyz="0 -0.046 0" rpy="0 -0 0"/>
      <geometry>
        <mesh filename="package://hrp5_p_description/meshes/HRP5Pmain/Rindex_Link1_mesh.dae" scale="1 1 1" />
      </geometry>
    </visual>
    <collision>
      <origin xyz="0 -0.046 0" rpy="0 -0 0"/>
      <geometry>
        <mesh filename="package://hrp5_p_description/meshes/HRP5Pmain/Rindex_Link1_mesh.dae" scale="1 1 1" />
      </geometry>
    </collision>
    <inertial>
      <mass value="0.023" />
      <origin xyz="0 -0.0172 0.0027" rpy="0 -0 0"/>
      <inertia ixx="1e-05" ixy="2.82315e-22" ixz="-7.95631e-24" iyy="2e-06" iyz="-1e-06" izz="1e-05"/>
    </inertial>
  </link>
  <gazebo reference="Rindex_Link1">
    <mu1>0.9</mu1>
    <mu2>0.9</mu2>
  </gazebo>
  <link name="Rindex_Link2">
    <visual>
      <origin xyz="0 -0.027 0" rpy="0 -0 0"/>
      <geometry>
        <mesh filename="package://hrp5_p_description/meshes/HRP5Pmain/Rindex_Link2_mesh.dae" scale="1 1 1" />
      </geometry>
    </visual>
    <collision>
      <origin xyz="0 -0.027 0" rpy="0 -0 0"/>
      <geometry>
        <mesh filename="package://hrp5_p_description/meshes/HRP5Pmain/Rindex_Link2_mesh.dae" scale="1 1 1" />
      </geometry>
    </collision>
    <inertial>
      <mass value="0.0137" />
      <origin xyz="0 -0.0119 0.0072" rpy="0 -0 0"/>
      <inertia ixx="4e-06" ixy="7.57715e-22" ixz="5.74055e-22" iyy="2e-06" iyz="-1e-06" izz="3e-06"/>
    </inertial>
  </link>
  <gazebo reference="Rindex_Link2">
    <mu1>0.9</mu1>
    <mu2>0.9</mu2>
  </gazebo>
  <link name="Rmiddle_Link0">
    <visual>
      <origin xyz="-0.03 -0.047 -0.114" rpy="-3.14159 -0 0"/>
      <geometry>
        <mesh filename="package://hrp5_p_description/meshes/HRP5Pmain/Rmiddle_Link0_mesh.dae" scale="1 1 1" />
      </geometry>
    </visual>
    <collision>
      <origin xyz="-0.03 -0.047 -0.114" rpy="-3.14159 -0 0"/>
      <geometry>
        <mesh filename="package://hrp5_p_description/meshes/HRP5Pmain/Rmiddle_Link0_mesh.dae" scale="1 1 1" />
      </geometry>
    </collision>
    <inertial>
      <mass value="0.0736" />
      <origin xyz="-0.0001 -0.0151 0.0023" rpy="0 -0 0"/>
      <inertia ixx="5.3e-05" ixy="3.78707e-21" ixz="-4.86833e-22" iyy="9e-06" iyz="-6e-06" izz="4.9e-05"/>
    </inertial>
  </link>
  <gazebo reference="Rmiddle_Link0">
    <mu1>0.9</mu1>
    <mu2>0.9</mu2>
  </gazebo>
  <link name="Rmiddle_Link1">
    <visual>
      <origin xyz="0 -0.046 0" rpy="0 -0 0"/>
      <geometry>
        <mesh filename="package://hrp5_p_description/meshes/HRP5Pmain/Rmiddle_Link1_mesh.dae" scale="1 1 1" />
      </geometry>
    </visual>
    <collision>
      <origin xyz="0 -0.046 0" rpy="0 -0 0"/>
      <geometry>
        <mesh filename="package://hrp5_p_description/meshes/HRP5Pmain/Rmiddle_Link1_mesh.dae" scale="1 1 1" />
      </geometry>
    </collision>
    <inertial>
      <mass value="0.023" />
      <origin xyz="0 -0.0172 0.0027" rpy="0 -0 0"/>
      <inertia ixx="1e-05" ixy="2.82315e-22" ixz="-7.95631e-24" iyy="2e-06" iyz="-1e-06" izz="1e-05"/>
    </inertial>
  </link>
  <gazebo reference="Rmiddle_Link1">
    <mu1>0.9</mu1>
    <mu2>0.9</mu2>
  </gazebo>
  <link name="Rmiddle_Link2">
    <visual>
      <origin xyz="0 -0.027 0" rpy="0 -0 0"/>
      <geometry>
        <mesh filename="package://hrp5_p_description/meshes/HRP5Pmain/Rmiddle_Link2_mesh.dae" scale="1 1 1" />
      </geometry>
    </visual>
    <collision>
      <origin xyz="0 -0.027 0" rpy="0 -0 0"/>
      <geometry>
        <mesh filename="package://hrp5_p_description/meshes/HRP5Pmain/Rmiddle_Link2_mesh.dae" scale="1 1 1" />
      </geometry>
    </collision>
    <inertial>
      <mass value="0.0137" />
      <origin xyz="0 -0.0119 0.0072" rpy="0 -0 0"/>
      <inertia ixx="4e-06" ixy="7.57715e-22" ixz="5.74055e-22" iyy="2e-06" iyz="-1e-06" izz="3e-06"/>
    </inertial>
  </link>
  <gazebo reference="Rmiddle_Link2">
    <mu1>0.9</mu1>
    <mu2>0.9</mu2>
  </gazebo>
  <link name="Rthumb_Link0">
    <visual>
      <origin xyz="0 0.047 -0.114" rpy="3.14159 -0 0"/>
      <geometry>
        <mesh filename="package://hrp5_p_description/meshes/HRP5Pmain/Rthumb_Link0_mesh.dae" scale="1 1 1" />
      </geometry>
    </visual>
    <collision>
      <origin xyz="0 0.047 -0.114" rpy="3.14159 -0 0"/>
      <geometry>
        <mesh filename="package://hrp5_p_description/meshes/HRP5Pmain/Rthumb_Link0_mesh.dae" scale="1 1 1" />
      </geometry>
    </collision>
    <inertial>
      <mass value="0.0732" />
      <origin xyz="0 0.0152 0.0023" rpy="0 -0 0"/>
      <inertia ixx="5.3e-05" ixy="-4.28374e-23" ixz="-3.88658e-22" iyy="9e-06" iyz="6e-06" izz="4.9e-05"/>
    </inertial>
  </link>
  <gazebo reference="Rthumb_Link0">
    <mu1>0.9</mu1>
    <mu2>0.9</mu2>
  </gazebo>
  <link name="Rthumb_Link1">
    <visual>
      <origin xyz="0 0.046 0" rpy="0 -0 0"/>
      <geometry>
        <mesh filename="package://hrp5_p_description/meshes/HRP5Pmain/Rthumb_Link1_mesh.dae" scale="1 1 1" />
      </geometry>
    </visual>
    <collision>
      <origin xyz="0 0.046 0" rpy="0 -0 0"/>
      <geometry>
        <mesh filename="package://hrp5_p_description/meshes/HRP5Pmain/Rthumb_Link1_mesh.dae" scale="1 1 1" />
      </geometry>
    </collision>
    <inertial>
      <mass value="0.023" />
      <origin xyz="0 0.0172 0.0027" rpy="0 -0 0"/>
      <inertia ixx="1e-05" ixy="-8.00493e-22" ixz="-3.118e-23" iyy="2e-06" iyz="1e-06" izz="1e-05"/>
    </inertial>
  </link>
  <gazebo reference="Rthumb_Link1">
    <mu1>0.9</mu1>
    <mu2>0.9</mu2>
  </gazebo>
  <link name="Rthumb_Link2">
    <visual>
      <origin xyz="0 0.027 0" rpy="0 -0 0"/>
      <geometry>
        <mesh filename="package://hrp5_p_description/meshes/HRP5Pmain/Rthumb_Link2_mesh.dae" scale="1 1 1" />
      </geometry>
    </visual>
    <collision>
      <origin xyz="0 0.027 0" rpy="0 -0 0"/>
      <geometry>
        <mesh filename="package://hrp5_p_description/meshes/HRP5Pmain/Rthumb_Link2_mesh.dae" scale="1 1 1" />
      </geometry>
    </collision>
    <inertial>
      <mass value="0.0137" />
      <origin xyz="0 0.0119 0.0072" rpy="0 -0 0"/>
      <inertia ixx="4e-06" ixy="-1.35052e-22" ixz="1.64464e-22" iyy="2e-06" iyz="1e-06" izz="3e-06"/>
    </inertial>
  </link>
  <gazebo reference="Rthumb_Link2">
    <mu1>0.9</mu1>
    <mu2>0.9</mu2>
  </gazebo>
  <joint name="LCY" type="revolute">
    <parent link="Body"/>
    <child  link="Lleg_Link0"/>
    <origin xyz="0 0.06 0" rpy="0 -0 0 "/>
    <axis   xyz="0 0 1"/>
    <limit lower="-0.785398" upper="0.785398" effort="250.912" velocity="10.295" />
    <dynamics damping="0.2" friction="0" />
  </joint>
  <transmission type="pr2_mechanism_model/SimpleTransmission" name="LCY_trans" >
    <actuator name="LCY_motor" />
    <joint name="LCY" />
    <mechanicalReduction>1</mechanicalReduction>
  </transmission>
  <gazebo reference="LCY">
    <cfmDamping>0.4</cfmDamping>
  </gazebo>
  <joint name="LCR" type="revolute">
    <parent link="Lleg_Link0"/>
    <child  link="Lleg_Link1"/>
    <origin xyz="0 0 0" rpy="0 -0 0 "/>
    <axis   xyz="1 0 0"/>
    <limit lower="-0.785398" upper="0.785398" effort="602.177" velocity="7.854" />
    <dynamics damping="0.2" friction="0" />
  </joint>
  <transmission type="pr2_mechanism_model/SimpleTransmission" name="LCR_trans" >
    <actuator name="LCR_motor" />
    <joint name="LCR" />
    <mechanicalReduction>1</mechanicalReduction>
  </transmission>
  <gazebo reference="LCR">
    <cfmDamping>0.4</cfmDamping>
  </gazebo>
  <joint name="LCP" type="revolute">
    <parent link="Lleg_Link1"/>
    <child  link="Lleg_Link2"/>
    <origin xyz="0 0 0" rpy="0 -0 0 "/>
    <axis   xyz="0 1 0"/>
    <limit lower="-2.18166" upper="1.3439" effort="602.177" velocity="8.579" />
    <dynamics damping="0.2" friction="0" />
  </joint>
  <transmission type="pr2_mechanism_model/SimpleTransmission" name="LCP_trans" >
    <actuator name="LCP_motor" />
    <joint name="LCP" />
    <mechanicalReduction>1</mechanicalReduction>
  </transmission>
  <gazebo reference="LCP">
    <cfmDamping>0.4</cfmDamping>
  </gazebo>
  <joint name="LKP" type="revolute">
    <parent link="Lleg_Link2"/>
    <child  link="Lleg_Link3"/>
    <origin xyz="0 0.035 -0.38" rpy="0 -0 0 "/>
    <axis   xyz="0 1 0"/>
    <limit lower="0" upper="2.61799" effort="1419.43" velocity="4.66" />
    <dynamics damping="0.2" friction="0" />
  </joint>
  <transmission type="pr2_mechanism_model/SimpleTransmission" name="LKP_trans" >
    <actuator name="LKP_motor" />
    <joint name="LKP" />
    <mechanicalReduction>1</mechanicalReduction>
  </transmission>
  <gazebo reference="LKP">
    <cfmDamping>0.4</cfmDamping>
  </gazebo>
  <joint name="LAP" type="revolute">
    <parent link="Lleg_Link3"/>
    <child  link="Lleg_Link4"/>
    <origin xyz="0 0 -0.38" rpy="0 -0 0 "/>
    <axis   xyz="0 1 0"/>
    <limit lower="-1.48353" upper="0.959931" effort="304.097" velocity="8.494" />
    <dynamics damping="0.2" friction="0" />
  </joint>
  <transmission type="pr2_mechanism_model/SimpleTransmission" name="LAP_trans" >
    <actuator name="LAP_motor" />
    <joint name="LAP" />
    <mechanicalReduction>1</mechanicalReduction>
  </transmission>
  <gazebo reference="LAP">
    <cfmDamping>0.4</cfmDamping>
  </gazebo>
  <joint name="LAR" type="revolute">
    <parent link="Lleg_Link4"/>
    <child  link="Lleg_Link5"/>
    <origin xyz="0 0 0" rpy="0 -0 0 "/>
    <axis   xyz="1 0 0"/>
    <limit lower="-0.785398" upper="0.872665" effort="253.423" velocity="10.193" />
    <dynamics damping="0.2" friction="0" />
  </joint>
  <transmission type="pr2_mechanism_model/SimpleTransmission" name="LAR_trans" >
    <actuator name="LAR_motor" />
    <joint name="LAR" />
    <mechanicalReduction>1</mechanicalReduction>
  </transmission>
  <gazebo reference="LAR">
    <cfmDamping>0.4</cfmDamping>
  </gazebo>
  <joint name="RCY" type="revolute">
    <parent link="Body"/>
    <child  link="Rleg_Link0"/>
    <origin xyz="0 -0.06 0" rpy="0 -0 0 "/>
    <axis   xyz="0 0 1"/>
    <limit lower="-0.785398" upper="0.785398" effort="250.912" velocity="10.295" />
    <dynamics damping="0.2" friction="0" />
  </joint>
  <transmission type="pr2_mechanism_model/SimpleTransmission" name="RCY_trans" >
    <actuator name="RCY_motor" />
    <joint name="RCY" />
    <mechanicalReduction>1</mechanicalReduction>
  </transmission>
  <gazebo reference="RCY">
    <cfmDamping>0.4</cfmDamping>
  </gazebo>
  <joint name="RCR" type="revolute">
    <parent link="Rleg_Link0"/>
    <child  link="Rleg_Link1"/>
    <origin xyz="0 0 0" rpy="0 -0 0 "/>
    <axis   xyz="1 0 0"/>
    <limit lower="-0.785398" upper="0.785398" effort="602.177" velocity="7.854" />
    <dynamics damping="0.2" friction="0" />
  </joint>
  <transmission type="pr2_mechanism_model/SimpleTransmission" name="RCR_trans" >
    <actuator name="RCR_motor" />
    <joint name="RCR" />
    <mechanicalReduction>1</mechanicalReduction>
  </transmission>
  <gazebo reference="RCR">
    <cfmDamping>0.4</cfmDamping>
  </gazebo>
  <joint name="RCP" type="revolute">
    <parent link="Rleg_Link1"/>
    <child  link="Rleg_Link2"/>
    <origin xyz="0 0 0" rpy="0 -0 0 "/>
    <axis   xyz="0 1 0"/>
    <limit lower="-2.18166" upper="1.3439" effort="602.177" velocity="8.579" />
    <dynamics damping="0.2" friction="0" />
  </joint>
  <transmission type="pr2_mechanism_model/SimpleTransmission" name="RCP_trans" >
    <actuator name="RCP_motor" />
    <joint name="RCP" />
    <mechanicalReduction>1</mechanicalReduction>
  </transmission>
  <gazebo reference="RCP">
    <cfmDamping>0.4</cfmDamping>
  </gazebo>
  <joint name="RKP" type="revolute">
    <parent link="Rleg_Link2"/>
    <child  link="Rleg_Link3"/>
    <origin xyz="0 -0.035 -0.38" rpy="0 -0 0 "/>
    <axis   xyz="0 1 0"/>
    <limit lower="0" upper="2.61799" effort="1419.43" velocity="4.66" />
    <dynamics damping="0.2" friction="0" />
  </joint>
  <transmission type="pr2_mechanism_model/SimpleTransmission" name="RKP_trans" >
    <actuator name="RKP_motor" />
    <joint name="RKP" />
    <mechanicalReduction>1</mechanicalReduction>
  </transmission>
  <gazebo reference="RKP">
    <cfmDamping>0.4</cfmDamping>
  </gazebo>
  <joint name="RAP" type="revolute">
    <parent link="Rleg_Link3"/>
    <child  link="Rleg_Link4"/>
    <origin xyz="0 0 -0.38" rpy="0 -0 0 "/>
    <axis   xyz="0 1 0"/>
    <limit lower="-1.48353" upper="0.959931" effort="304.097" velocity="8.494" />
    <dynamics damping="0.2" friction="0" />
  </joint>
  <transmission type="pr2_mechanism_model/SimpleTransmission" name="RAP_trans" >
    <actuator name="RAP_motor" />
    <joint name="RAP" />
    <mechanicalReduction>1</mechanicalReduction>
  </transmission>
  <gazebo reference="RAP">
    <cfmDamping>0.4</cfmDamping>
  </gazebo>
  <joint name="RAR" type="revolute">
    <parent link="Rleg_Link4"/>
    <child  link="Rleg_Link5"/>
    <origin xyz="0 0 0" rpy="0 -0 0 "/>
    <axis   xyz="1 0 0"/>
    <limit lower="-0.872665" upper="0.785398" effort="253.423" velocity="10.193" />
    <dynamics damping="0.2" friction="0" />
  </joint>
  <transmission type="pr2_mechanism_model/SimpleTransmission" name="RAR_trans" >
    <actuator name="RAR_motor" />
    <joint name="RAR" />
    <mechanicalReduction>1</mechanicalReduction>
  </transmission>
  <gazebo reference="RAR">
    <cfmDamping>0.4</cfmDamping>
  </gazebo>
  <joint name="WP" type="revolute">
    <parent link="Body"/>
    <child  link="Chest_Link0"/>
    <origin xyz="0.055 0 0.274" rpy="0 -0 0 "/>
    <axis   xyz="0 1 0"/>
    <limit lower="-0.20944" upper="1.5708" effort="946.286" velocity="5.459" />
    <dynamics damping="0.2" friction="0" />
  </joint>
  <transmission type="pr2_mechanism_model/SimpleTransmission" name="WP_trans" >
    <actuator name="WP_motor" />
    <joint name="WP" />
    <mechanicalReduction>1</mechanicalReduction>
  </transmission>
  <gazebo reference="WP">
    <cfmDamping>0.4</cfmDamping>
  </gazebo>
  <joint name="WR" type="revolute">
    <parent link="Chest_Link0"/>
    <child  link="Chest_Link1"/>
    <origin xyz="0 0 0" rpy="0 -0 0 "/>
    <axis   xyz="1 0 0"/>
    <limit lower="-0.785398" upper="0.785398" effort="946.286" velocity="5.46" />
    <dynamics damping="0.2" friction="0" />
  </joint>
  <transmission type="pr2_mechanism_model/SimpleTransmission" name="WR_trans" >
    <actuator name="WR_motor" />
    <joint name="WR" />
    <mechanicalReduction>1</mechanicalReduction>
  </transmission>
  <gazebo reference="WR">
    <cfmDamping>0.4</cfmDamping>
  </gazebo>
  <joint name="WY" type="revolute">
    <parent link="Chest_Link1"/>
    <child  link="Chest_Link2"/>
    <origin xyz="0 0 0" rpy="0 -0 0 "/>
    <axis   xyz="0 0 1"/>
    <limit lower="-1.91986" upper="3.31613" effort="301.088" velocity="7.854" />
    <dynamics damping="0.2" friction="0" />
  </joint>
  <transmission type="pr2_mechanism_model/SimpleTransmission" name="WY_trans" >
    <actuator name="WY_motor" />
    <joint name="WY" />
    <mechanicalReduction>1</mechanicalReduction>
  </transmission>
  <gazebo reference="WY">
    <cfmDamping>0.4</cfmDamping>
  </gazebo>
  <joint name="HY" type="revolute">
    <parent link="Chest_Link2"/>
    <child  link="Head_Link0"/>
    <origin xyz="0.032 0 0.549" rpy="0 -0 0 "/>
    <axis   xyz="0 0 1"/>
    <limit lower="-3.31613" upper="1.91986" effort="52.1196" velocity="7.002" />
    <dynamics damping="0.2" friction="0" />
  </joint>
  <transmission type="pr2_mechanism_model/SimpleTransmission" name="HY_trans" >
    <actuator name="HY_motor" />
    <joint name="HY" />
    <mechanicalReduction>1</mechanicalReduction>
  </transmission>
  <gazebo reference="HY">
    <cfmDamping>0.4</cfmDamping>
  </gazebo>
  <joint name="HP" type="revolute">
    <parent link="Head_Link0"/>
    <child  link="Head_Link1_Plan2"/>
    <origin xyz="0.04 0 0" rpy="0 -0 0 "/>
    <axis   xyz="0 1 0"/>
    <limit lower="-1.65806" upper="1.5708" effort="52.6388" velocity="6.933" />
    <dynamics damping="0.2" friction="0" />
  </joint>
  <transmission type="pr2_mechanism_model/SimpleTransmission" name="HP_trans" >
    <actuator name="HP_motor" />
    <joint name="HP" />
    <mechanicalReduction>1</mechanicalReduction>
  </transmission>
  <gazebo reference="HP">
    <cfmDamping>0.4</cfmDamping>
  </gazebo>
  <joint name="azure_depth_frame_joint" type="fixed">
    <parent link="Head_Link1_Plan2"/>
    <child  link="azure_depth_frame"/>
    <origin xyz="0.116667 0.0106775 0.0391359" rpy="-1.6814 -0.00382783 -1.56383 "/>
    <axis   xyz="0 0 1"/>
    <limit lower="0" upper="0" effort="100" velocity="0.5" />
    <dynamics damping="0.2" friction="0" />
  </joint>
  <transmission type="pr2_mechanism_model/SimpleTransmission" name="azure_depth_frame_joint_trans" >
    <actuator name="azure_depth_frame_joint_motor" />
    <joint name="azure_depth_frame_joint" />
    <mechanicalReduction>1</mechanicalReduction>
  </transmission>
  <gazebo reference="azure_depth_frame_joint">
    <cfmDamping>0.4</cfmDamping>
  </gazebo>
  <joint name="head_root_joint" type="fixed">
    <parent link="Head_Link1_Plan2"/>
    <child  link="head_root"/>
    <origin xyz="0.0674119 0.00139956 0.0431723" rpy="3.13785 0.00200063 0.00354426 "/>
    <axis   xyz="0 0 1"/>
    <limit lower="0" upper="0" effort="100" velocity="0.5" />
    <dynamics damping="0.2" friction="0" />
  </joint>
  <transmission type="pr2_mechanism_model/SimpleTransmission" name="head_root_joint_trans" >
    <actuator name="head_root_joint_motor" />
    <joint name="head_root_joint" />
    <mechanicalReduction>1</mechanicalReduction>
  </transmission>
  <gazebo reference="head_root_joint">
    <cfmDamping>0.4</cfmDamping>
  </gazebo>
  <joint name="left_camera_optical_frame_joint" type="fixed">
    <parent link="head_root"/>
    <child  link="left_camera_optical_frame"/>
    <origin xyz="0 0.035 -0.002" rpy="-1.571 6.27254e-07 -1.571 "/>
    <axis   xyz="0 0 1"/>
    <limit lower="0" upper="0" effort="100" velocity="0.5" />
    <dynamics damping="0.2" friction="0" />
  </joint>
  <transmission type="pr2_mechanism_model/SimpleTransmission" name="left_camera_optical_frame_joint_trans" >
    <actuator name="left_camera_optical_frame_joint_motor" />
    <joint name="left_camera_optical_frame_joint" />
    <mechanicalReduction>1</mechanicalReduction>
  </transmission>
  <gazebo reference="left_camera_optical_frame_joint">
    <cfmDamping>0.4</cfmDamping>
  </gazebo>
  <joint name="left_camera_optical_joint" type="fixed">
    <parent link="left_camera_optical_frame"/>
    <child  link="motor"/>
    <origin xyz="0.023 -0.08 -0.003" rpy="0 -0 0.532153 "/>
    <axis   xyz="0 0 1"/>
    <limit lower="0" upper="0" effort="100" velocity="0.5" />
    <dynamics damping="0.2" friction="0" />
  </joint>
  <transmission type="pr2_mechanism_model/SimpleTransmission" name="left_camera_optical_joint_trans" >
    <actuator name="left_camera_optical_joint_motor" />
    <joint name="left_camera_optical_joint" />
    <mechanicalReduction>1</mechanicalReduction>
  </transmission>
  <gazebo reference="left_camera_optical_joint">
    <cfmDamping>0.4</cfmDamping>
  </gazebo>
  <joint name="motor_joint" type="continuous">
    <parent link="motor"/>
    <child  link="spindle"/>
    <origin xyz="0 0 0" rpy="0 -0 0 "/>
    <axis   xyz="0 0 1"/>
    <limit lower="-3.14159" upper="3.14159" effort="100" velocity="0.5" />
    <dynamics damping="0.2" friction="0" />
  </joint>
  <transmission type="pr2_mechanism_model/SimpleTransmission" name="motor_joint_trans" >
    <actuator name="motor_joint_motor" />
    <joint name="motor_joint" />
    <mechanicalReduction>1</mechanicalReduction>
  </transmission>
  <gazebo reference="motor_joint">
    <cfmDamping>0.4</cfmDamping>
  </gazebo>
  <joint name="hokuyo_link_joint" type="fixed">
    <parent link="spindle"/>
    <child  link="hokuyo_link"/>
    <origin xyz="0.001 0.02 0" rpy="-1.52321 -1.52875 -0.0475831 "/>
    <axis   xyz="0 0 1"/>
    <limit lower="0" upper="0" effort="100" velocity="0.5" />
    <dynamics damping="0.2" friction="0" />
  </joint>
  <transmission type="pr2_mechanism_model/SimpleTransmission" name="hokuyo_link_joint_trans" >
    <actuator name="hokuyo_link_joint_motor" />
    <joint name="hokuyo_link_joint" />
    <mechanicalReduction>1</mechanicalReduction>
  </transmission>
  <gazebo reference="hokuyo_link_joint">
    <cfmDamping>0.4</cfmDamping>
  </gazebo>
  <joint name="head_hokuyo_frame_joint" type="fixed">
    <parent link="hokuyo_link"/>
    <child  link="head_hokuyo_frame"/>
    <origin xyz="0 0 0" rpy="0 -1.5708 4.71239 "/>
    <axis   xyz="0 0 1"/>
    <limit lower="0" upper="0" effort="100" velocity="0.5" />
    <dynamics damping="0.2" friction="0" />
  </joint>
  <transmission type="pr2_mechanism_model/SimpleTransmission" name="head_hokuyo_frame_joint_trans" >
    <actuator name="head_hokuyo_frame_joint_motor" />
    <joint name="head_hokuyo_frame_joint" />
    <mechanicalReduction>1</mechanicalReduction>
  </transmission>
  <gazebo reference="head_hokuyo_frame_joint">
    <cfmDamping>0.4</cfmDamping>
  </gazebo>
  <joint name="right_camera_optical_frame_joint" type="fixed">
    <parent link="head_root"/>
    <child  link="right_camera_optical_frame"/>
    <origin xyz="0 -0.035 -0.002" rpy="-1.571 6.27254e-07 -1.571 "/>
    <axis   xyz="0 0 1"/>
    <limit lower="0" upper="0" effort="100" velocity="0.5" />
    <dynamics damping="0.2" friction="0" />
  </joint>
  <transmission type="pr2_mechanism_model/SimpleTransmission" name="right_camera_optical_frame_joint_trans" >
    <actuator name="right_camera_optical_frame_joint_motor" />
    <joint name="right_camera_optical_frame_joint" />
    <mechanicalReduction>1</mechanicalReduction>
  </transmission>
  <gazebo reference="right_camera_optical_frame_joint">
    <cfmDamping>0.4</cfmDamping>
  </gazebo>
  <joint name="realsense_link_joint" type="fixed">
    <parent link="Head_Link1_Plan2"/>
    <child  link="realsense_link"/>
    <origin xyz="0.0488744 0.0201369 0.102385" rpy="-0.0147126 0.0482361 -0.00469497 "/>
    <axis   xyz="0 0 1"/>
    <limit lower="0" upper="0" effort="100" velocity="0.5" />
    <dynamics damping="0.2" friction="0" />
  </joint>
  <transmission type="pr2_mechanism_model/SimpleTransmission" name="realsense_link_joint_trans" >
    <actuator name="realsense_link_joint_motor" />
    <joint name="realsense_link_joint" />
    <mechanicalReduction>1</mechanicalReduction>
  </transmission>
  <gazebo reference="realsense_link_joint">
    <cfmDamping>0.4</cfmDamping>
  </gazebo>
  <joint name="realsense_aligned_depth_to_color_frame_joint" type="fixed">
    <parent link="realsense_link"/>
    <child  link="realsense_aligned_depth_to_color_frame"/>
    <origin xyz="-0.001 0.015 0" rpy="-0.00799796 0.00200797 0.00199197 "/>
    <axis   xyz="0 0 1"/>
    <limit lower="0" upper="0" effort="100" velocity="0.5" />
    <dynamics damping="0.2" friction="0" />
  </joint>
  <transmission type="pr2_mechanism_model/SimpleTransmission" name="realsense_aligned_depth_to_color_frame_joint_trans" >
    <actuator name="realsense_aligned_depth_to_color_frame_joint_motor" />
    <joint name="realsense_aligned_depth_to_color_frame_joint" />
    <mechanicalReduction>1</mechanicalReduction>
  </transmission>
  <gazebo reference="realsense_aligned_depth_to_color_frame_joint">
    <cfmDamping>0.4</cfmDamping>
  </gazebo>
  <joint name="realsense_color_optical_joint" type="fixed">
    <parent link="realsense_aligned_depth_to_color_frame"/>
    <child  link="realsense_color_optical_frame"/>
    <origin xyz="0 0 0" rpy="-1.5708 3.33067e-16 -1.5708 "/>
    <axis   xyz="0 0 1"/>
    <limit lower="0" upper="0" effort="100" velocity="0.5" />
    <dynamics damping="0.2" friction="0" />
  </joint>
  <transmission type="pr2_mechanism_model/SimpleTransmission" name="realsense_color_optical_joint_trans" >
    <actuator name="realsense_color_optical_joint_motor" />
    <joint name="realsense_color_optical_joint" />
    <mechanicalReduction>1</mechanicalReduction>
  </transmission>
  <gazebo reference="realsense_color_optical_joint">
    <cfmDamping>0.4</cfmDamping>
  </gazebo>
  <joint name="realsense_color_frame_joint" type="fixed">
    <parent link="realsense_link"/>
    <child  link="realsense_color_frame"/>
    <origin xyz="-0.001 0.015 0" rpy="-0.00799796 0.00200797 0.00199197 "/>
    <axis   xyz="0 0 1"/>
    <limit lower="0" upper="0" effort="100" velocity="0.5" />
    <dynamics damping="0.2" friction="0" />
  </joint>
  <transmission type="pr2_mechanism_model/SimpleTransmission" name="realsense_color_frame_joint_trans" >
    <actuator name="realsense_color_frame_joint_motor" />
    <joint name="realsense_color_frame_joint" />
    <mechanicalReduction>1</mechanicalReduction>
  </transmission>
  <gazebo reference="realsense_color_frame_joint">
    <cfmDamping>0.4</cfmDamping>
  </gazebo>
  <joint name="realsense_depth_joint" type="fixed">
    <parent link="realsense_link"/>
    <child  link="realsense_depth_frame"/>
    <origin xyz="0 0 0" rpy="0 -0 0 "/>
    <axis   xyz="0 0 1"/>
    <limit lower="0" upper="0" effort="100" velocity="0.5" />
    <dynamics damping="0.2" friction="0" />
  </joint>
  <transmission type="pr2_mechanism_model/SimpleTransmission" name="realsense_depth_joint_trans" >
    <actuator name="realsense_depth_joint_motor" />
    <joint name="realsense_depth_joint" />
    <mechanicalReduction>1</mechanicalReduction>
  </transmission>
  <gazebo reference="realsense_depth_joint">
    <cfmDamping>0.4</cfmDamping>
  </gazebo>
  <joint name="realsense_depth_optical_joint" type="fixed">
    <parent link="realsense_depth_frame"/>
    <child  link="realsense_depth_optical_frame"/>
    <origin xyz="0 0 0" rpy="-1.5708 3.33067e-16 -1.5708 "/>
    <axis   xyz="0 0 1"/>
    <limit lower="0" upper="0" effort="100" velocity="0.5" />
    <dynamics damping="0.2" friction="0" />
  </joint>
  <transmission type="pr2_mechanism_model/SimpleTransmission" name="realsense_depth_optical_joint_trans" >
    <actuator name="realsense_depth_optical_joint_motor" />
    <joint name="realsense_depth_optical_joint" />
    <mechanicalReduction>1</mechanicalReduction>
  </transmission>
  <gazebo reference="realsense_depth_optical_joint">
    <cfmDamping>0.4</cfmDamping>
  </gazebo>
  <joint name="LSC" type="revolute">
    <parent link="Chest_Link2"/>
    <child  link="Lscap_Link0"/>
    <origin xyz="0.032 0.08 0.268" rpy="0 -0 0 "/>
    <axis   xyz="0 0 1"/>
    <limit lower="-1.0472" upper="0.349066" effort="250.912" velocity="7.854" />
    <dynamics damping="0.2" friction="0" />
  </joint>
  <transmission type="pr2_mechanism_model/SimpleTransmission" name="LSC_trans" >
    <actuator name="LSC_motor" />
    <joint name="LSC" />
    <mechanicalReduction>1</mechanicalReduction>
  </transmission>
  <gazebo reference="LSC">
    <cfmDamping>0.4</cfmDamping>
  </gazebo>
  <joint name="LSP" type="revolute">
    <parent link="Lscap_Link0"/>
    <child  link="Larm_Link0"/>
    <origin xyz="0 0.13 0" rpy="0 -0 0 "/>
    <axis   xyz="0 1 0"/>
    <limit lower="-3.49066" upper="1.22173" effort="473.143" velocity="4.165" />
    <dynamics damping="0.2" friction="0" />
  </joint>
  <transmission type="pr2_mechanism_model/SimpleTransmission" name="LSP_trans" >
    <actuator name="LSP_motor" />
    <joint name="LSP" />
    <mechanicalReduction>1</mechanicalReduction>
  </transmission>
  <gazebo reference="LSP">
    <cfmDamping>0.4</cfmDamping>
  </gazebo>
  <joint name="LSR" type="revolute">
    <parent link="Larm_Link0"/>
    <child  link="Larm_Link1"/>
    <origin xyz="0 0 0" rpy="0 -0 0 "/>
    <axis   xyz="1 0 0"/>
    <limit lower="-0.436332" upper="1.65806" effort="398.229" velocity="6.487" />
    <dynamics damping="0.2" friction="0" />
  </joint>
  <transmission type="pr2_mechanism_model/SimpleTransmission" name="LSR_trans" >
    <actuator name="LSR_motor" />
    <joint name="LSR" />
    <mechanicalReduction>1</mechanicalReduction>
  </transmission>
  <gazebo reference="LSR">
    <cfmDamping>0.4</cfmDamping>
  </gazebo>
  <joint name="LSY" type="revolute">
    <parent link="Larm_Link1"/>
    <child  link="Larm_Link2"/>
    <origin xyz="0 0.02 0" rpy="0 -0 0 "/>
    <axis   xyz="0 0 1"/>
    <limit lower="-2.0944" upper="1.6057" effort="250.912" velocity="7.854" />
    <dynamics damping="0.2" friction="0" />
  </joint>
  <transmission type="pr2_mechanism_model/SimpleTransmission" name="LSY_trans" >
    <actuator name="LSY_motor" />
    <joint name="LSY" />
    <mechanicalReduction>1</mechanicalReduction>
  </transmission>
  <gazebo reference="LSY">
    <cfmDamping>0.4</cfmDamping>
  </gazebo>
  <joint name="LEP" type="revolute">
    <parent link="Larm_Link2"/>
    <child  link="Larm_Link3"/>
    <origin xyz="0.05 0 -0.295804" rpy="0 -0 0 "/>
    <axis   xyz="0 1 0"/>
    <limit lower="-3.14159" upper="-0.282743" effort="431.25" velocity="5.99" />
    <dynamics damping="0.2" friction="0" />
  </joint>
  <transmission type="pr2_mechanism_model/SimpleTransmission" name="LEP_trans" >
    <actuator name="LEP_motor" />
    <joint name="LEP" />
    <mechanicalReduction>1</mechanicalReduction>
  </transmission>
  <gazebo reference="LEP">
    <cfmDamping>0.4</cfmDamping>
  </gazebo>
  <joint name="LWRY" type="revolute">
    <parent link="Larm_Link3"/>
    <child  link="Larm_Link4"/>
    <origin xyz="-0.05 0 -0.295804" rpy="0 -0 0 "/>
    <axis   xyz="0 0 1"/>
    <limit lower="-3.1765" upper="2.1293" effort="382.5" velocity="6.66" />
    <dynamics damping="0.2" friction="0" />
  </joint>
  <transmission type="pr2_mechanism_model/SimpleTransmission" name="LWRY_trans" >
    <actuator name="LWRY_motor" />
    <joint name="LWRY" />
    <mechanicalReduction>1</mechanicalReduction>
  </transmission>
  <gazebo reference="LWRY">
    <cfmDamping>0.4</cfmDamping>
  </gazebo>
  <joint name="LWRR" type="revolute">
    <parent link="Larm_Link4"/>
    <child  link="Larm_Link5"/>
    <origin xyz="0 0 0" rpy="0 -0 0 "/>
    <axis   xyz="1 0 0"/>
    <limit lower="-1.22173" upper="0.820305" effort="359.184" velocity="4.865" />
    <dynamics damping="0.2" friction="0" />
  </joint>
  <transmission type="pr2_mechanism_model/SimpleTransmission" name="LWRR_trans" >
    <actuator name="LWRR_motor" />
    <joint name="LWRR" />
    <mechanicalReduction>1</mechanicalReduction>
  </transmission>
  <gazebo reference="LWRR">
    <cfmDamping>0.4</cfmDamping>
  </gazebo>
  <joint name="LWRP" type="revolute">
    <parent link="Larm_Link5"/>
    <child  link="Larm_Link6"/>
    <origin xyz="0 0 0" rpy="0 -0 0 "/>
    <axis   xyz="0 1 0"/>
    <limit lower="-0.733038" upper="0.733038" effort="158.714" velocity="4.817" />
    <dynamics damping="0.2" friction="0" />
  </joint>
  <transmission type="pr2_mechanism_model/SimpleTransmission" name="LWRP_trans" >
    <actuator name="LWRP_motor" />
    <joint name="LWRP" />
    <mechanicalReduction>1</mechanicalReduction>
  </transmission>
  <gazebo reference="LWRP">
    <cfmDamping>0.4</cfmDamping>
  </gazebo>
  <joint name="LHDY" type="revolute">
    <parent link="Larm_Link6"/>
    <child  link="Lhand_Link0_Plan2"/>
    <origin xyz="0 -0.017324 -0.078842" rpy="-0.785398 0 0 "/>
    <axis   xyz="0 0 1"/>
    <limit lower="-2.61799" upper="2.61799" effort="33.7995" velocity="4.803" />
    <dynamics damping="0.2" friction="0" />
  </joint>
  <transmission type="pr2_mechanism_model/SimpleTransmission" name="LHDY_trans" >
    <actuator name="LHDY_motor" />
    <joint name="LHDY" />
    <mechanicalReduction>1</mechanicalReduction>
  </transmission>
  <gazebo reference="LHDY">
    <cfmDamping>0.4</cfmDamping>
  </gazebo>

  <joint name="hammer_root" type="fixed">
    <parent link="Lhand_Link0_Plan2"/>
    <child  link="Hammer"/>
    <origin xyz="0 -0.024 0" rpy="0 1.57 0"/>
  </joint>

  <joint name="hammer_head" type="fixed">
    <parent link="Hammer"/>
    <child  link="Hammer_Head"/>
    <origin xyz="0.17 0.01 0.21" rpy="1.57 0.0 0.0"/>
  </joint>

  <joint name="LIMP" type="revolute">
    <mimic joint="LTMP" multiplier="-1" offset="0" />
    <parent link="Lhand_Link0_Plan2"/>
    <child  link="Lindex_Link0"/>
    <origin xyz="0.03 0.047 -0.114" rpy="3.14159 -0 0 "/>
    <axis   xyz="1 0 0"/>
    <limit lower="0.05236" upper="2.0944" effort="38.7743" velocity="1.963" />
    <dynamics damping="0.2" friction="0" />
  </joint>
  <transmission type="pr2_mechanism_model/SimpleTransmission" name="LIMP_trans" >
    <actuator name="LIMP_motor" />
    <joint name="LIMP" />
    <mechanicalReduction>1</mechanicalReduction>
  </transmission>
  <gazebo reference="LIMP">
    <cfmDamping>0.4</cfmDamping>
  </gazebo>
  <joint name="LIPIP" type="revolute">
    <mimic joint="LTMP" multiplier="0" offset="0" />
    <parent link="Lindex_Link0"/>
    <child  link="Lindex_Link1"/>
    <origin xyz="0 0.046 0" rpy="0 -0 0 "/>
    <axis   xyz="1 0 0"/>
    <limit lower="-1.5708" upper="0" effort="38.7743" velocity="1.963" />
    <dynamics damping="0.2" friction="0" />
  </joint>
  <transmission type="pr2_mechanism_model/SimpleTransmission" name="LIPIP_trans" >
    <actuator name="LIPIP_motor" />
    <joint name="LIPIP" />
    <mechanicalReduction>1</mechanicalReduction>
  </transmission>
  <gazebo reference="LIPIP">
    <cfmDamping>0.4</cfmDamping>
  </gazebo>
  <joint name="LIDIP" type="revolute">
    <mimic joint="LTMP" multiplier="0" offset="0" />
    <parent link="Lindex_Link1"/>
    <child  link="Lindex_Link2"/>
    <origin xyz="0 0.027 0" rpy="0 -0 0 "/>
    <axis   xyz="1 0 0"/>
    <limit lower="-2.16717" upper="0" effort="38.7743" velocity="1.963" />
    <dynamics damping="0.2" friction="0" />
  </joint>
  <transmission type="pr2_mechanism_model/SimpleTransmission" name="LIDIP_trans" >
    <actuator name="LIDIP_motor" />
    <joint name="LIDIP" />
    <mechanicalReduction>1</mechanicalReduction>
  </transmission>
  <gazebo reference="LIDIP">
    <cfmDamping>0.4</cfmDamping>
  </gazebo>
  <joint name="LMMP" type="revolute">
    <mimic joint="LTMP" multiplier="-1" offset="0" />
    <parent link="Lhand_Link0_Plan2"/>
    <child  link="Lmiddle_Link0"/>
    <origin xyz="-0.03 0.047 -0.114" rpy="3.14159 -0 0 "/>
    <axis   xyz="1 0 0"/>
    <limit lower="0.05236" upper="2.0944" effort="38.7743" velocity="1.963" />
    <dynamics damping="0.2" friction="0" />
  </joint>
  <transmission type="pr2_mechanism_model/SimpleTransmission" name="LMMP_trans" >
    <actuator name="LMMP_motor" />
    <joint name="LMMP" />
    <mechanicalReduction>1</mechanicalReduction>
  </transmission>
  <gazebo reference="LMMP">
    <cfmDamping>0.4</cfmDamping>
  </gazebo>
  <joint name="LMPIP" type="revolute">
    <mimic joint="LTMP" multiplier="0" offset="0" />
    <parent link="Lmiddle_Link0"/>
    <child  link="Lmiddle_Link1"/>
    <origin xyz="0 0.046 0" rpy="0 -0 0 "/>
    <axis   xyz="1 0 0"/>
    <limit lower="-1.5708" upper="0" effort="38.7743" velocity="1.963" />
    <dynamics damping="0.2" friction="0" />
  </joint>
  <transmission type="pr2_mechanism_model/SimpleTransmission" name="LMPIP_trans" >
    <actuator name="LMPIP_motor" />
    <joint name="LMPIP" />
    <mechanicalReduction>1</mechanicalReduction>
  </transmission>
  <gazebo reference="LMPIP">
    <cfmDamping>0.4</cfmDamping>
  </gazebo>
  <joint name="LMDIP" type="revolute">
    <mimic joint="LTMP" multiplier="0" offset="0" />
    <parent link="Lmiddle_Link1"/>
    <child  link="Lmiddle_Link2"/>
    <origin xyz="0 0.027 0" rpy="0 -0 0 "/>
    <axis   xyz="1 0 0"/>
    <limit lower="-2.16717" upper="0" effort="38.7743" velocity="1.963" />
    <dynamics damping="0.2" friction="0" />
  </joint>
  <transmission type="pr2_mechanism_model/SimpleTransmission" name="LMDIP_trans" >
    <actuator name="LMDIP_motor" />
    <joint name="LMDIP" />
    <mechanicalReduction>1</mechanicalReduction>
  </transmission>
  <gazebo reference="LMDIP">
    <cfmDamping>0.4</cfmDamping>
  </gazebo>
  <joint name="LTMP" type="revolute">
    <parent link="Lhand_Link0_Plan2"/>
    <child  link="Lthumb_Link0"/>
    <origin xyz="0 -0.047 -0.114" rpy="-3.14159 -0 0 "/>
    <axis   xyz="1 0 0"/>
    <limit lower="-2.00713" upper="-0.0872665" effort="38.7742" velocity="1.923" />
    <dynamics damping="0.2" friction="0" />
  </joint>
  <transmission type="pr2_mechanism_model/SimpleTransmission" name="LTMP_trans" >
    <actuator name="LTMP_motor" />
    <joint name="LTMP" />
    <mechanicalReduction>1</mechanicalReduction>
  </transmission>
  <gazebo reference="LTMP">
    <cfmDamping>0.4</cfmDamping>
  </gazebo>
  <joint name="LTPIP" type="revolute">
    <mimic joint="LTMP" multiplier="0" offset="0" />
    <parent link="Lthumb_Link0"/>
    <child  link="Lthumb_Link1"/>
    <origin xyz="0 -0.046 0" rpy="0 -0 0 "/>
    <axis   xyz="1 0 0"/>
    <limit lower="0" upper="1.5708" effort="38.7743" velocity="1.963" />
    <dynamics damping="0.2" friction="0" />
  </joint>
  <transmission type="pr2_mechanism_model/SimpleTransmission" name="LTPIP_trans" >
    <actuator name="LTPIP_motor" />
    <joint name="LTPIP" />
    <mechanicalReduction>1</mechanicalReduction>
  </transmission>
  <gazebo reference="LTPIP">
    <cfmDamping>0.4</cfmDamping>
  </gazebo>
  <joint name="LTDIP" type="revolute">
    <mimic joint="LTMP" multiplier="0" offset="0" />
    <parent link="Lthumb_Link1"/>
    <child  link="Lthumb_Link2"/>
    <origin xyz="0 -0.027 0" rpy="0 -0 0 "/>
    <axis   xyz="1 0 0"/>
    <limit lower="0" upper="2.16717" effort="38.7743" velocity="1.963" />
    <dynamics damping="0.2" friction="0" />
  </joint>
  <transmission type="pr2_mechanism_model/SimpleTransmission" name="LTDIP_trans" >
    <actuator name="LTDIP_motor" />
    <joint name="LTDIP" />
    <mechanicalReduction>1</mechanicalReduction>
  </transmission>
  <gazebo reference="LTDIP">
    <cfmDamping>0.4</cfmDamping>
  </gazebo>
  <joint name="RSC" type="revolute">
    <parent link="Chest_Link2"/>
    <child  link="Rscap_Link0"/>
    <origin xyz="0.032 -0.08 0.268" rpy="0 -0 0 "/>
    <axis   xyz="0 0 1"/>
    <limit lower="-0.349066" upper="1.0472" effort="250.912" velocity="7.854" />
    <dynamics damping="0.2" friction="0" />
  </joint>
  <transmission type="pr2_mechanism_model/SimpleTransmission" name="RSC_trans" >
    <actuator name="RSC_motor" />
    <joint name="RSC" />
    <mechanicalReduction>1</mechanicalReduction>
  </transmission>
  <gazebo reference="RSC">
    <cfmDamping>0.4</cfmDamping>
  </gazebo>
  <joint name="RSP" type="revolute">
    <parent link="Rscap_Link0"/>
    <child  link="Rarm_Link0"/>
    <origin xyz="0 -0.13 0" rpy="0 -0 0 "/>
    <axis   xyz="0 1 0"/>
    <limit lower="-3.49066" upper="1.22173" effort="473.143" velocity="4.165" />
    <dynamics damping="0.2" friction="0" />
  </joint>
  <transmission type="pr2_mechanism_model/SimpleTransmission" name="RSP_trans" >
    <actuator name="RSP_motor" />
    <joint name="RSP" />
    <mechanicalReduction>1</mechanicalReduction>
  </transmission>
  <gazebo reference="RSP">
    <cfmDamping>0.4</cfmDamping>
  </gazebo>
  <joint name="RSR" type="revolute">
    <parent link="Rarm_Link0"/>
    <child  link="Rarm_Link1"/>
    <origin xyz="0 0 0" rpy="0 -0 0 "/>
    <axis   xyz="1 0 0"/>
    <limit lower="-1.65806" upper="0.436332" effort="398.229" velocity="6.487" />
    <dynamics damping="0.2" friction="0" />
  </joint>
  <transmission type="pr2_mechanism_model/SimpleTransmission" name="RSR_trans" >
    <actuator name="RSR_motor" />
    <joint name="RSR" />
    <mechanicalReduction>1</mechanicalReduction>
  </transmission>
  <gazebo reference="RSR">
    <cfmDamping>0.4</cfmDamping>
  </gazebo>
  <joint name="RSY" type="revolute">
    <parent link="Rarm_Link1"/>
    <child  link="Rarm_Link2"/>
    <origin xyz="0 -0.02 0" rpy="0 -0 0 "/>
    <axis   xyz="0 0 1"/>
    <limit lower="-1.6057" upper="2.0944" effort="250.912" velocity="7.854" />
    <dynamics damping="0.2" friction="0" />
  </joint>
  <transmission type="pr2_mechanism_model/SimpleTransmission" name="RSY_trans" >
    <actuator name="RSY_motor" />
    <joint name="RSY" />
    <mechanicalReduction>1</mechanicalReduction>
  </transmission>
  <gazebo reference="RSY">
    <cfmDamping>0.4</cfmDamping>
  </gazebo>
  <joint name="REP" type="revolute">
    <parent link="Rarm_Link2"/>
    <child  link="Rarm_Link3"/>
    <origin xyz="0.05 0 -0.295804" rpy="0 -0 0 "/>
    <axis   xyz="0 1 0"/>
    <limit lower="-3.14159" upper="-0.282743" effort="431.25" velocity="5.99" />
    <dynamics damping="0.2" friction="0" />
  </joint>
  <transmission type="pr2_mechanism_model/SimpleTransmission" name="REP_trans" >
    <actuator name="REP_motor" />
    <joint name="REP" />
    <mechanicalReduction>1</mechanicalReduction>
  </transmission>
  <gazebo reference="REP">
    <cfmDamping>0.4</cfmDamping>
  </gazebo>
  <joint name="RWRY" type="revolute">
    <parent link="Rarm_Link3"/>
    <child  link="Rarm_Link4"/>
    <origin xyz="-0.05 0 -0.295804" rpy="0 -0 0 "/>
    <axis   xyz="0 0 1"/>
    <limit lower="-2.1293" upper="3.1765" effort="382.5" velocity="6.66" />
    <dynamics damping="0.2" friction="0" />
  </joint>
  <transmission type="pr2_mechanism_model/SimpleTransmission" name="RWRY_trans" >
    <actuator name="RWRY_motor" />
    <joint name="RWRY" />
    <mechanicalReduction>1</mechanicalReduction>
  </transmission>
  <gazebo reference="RWRY">
    <cfmDamping>0.4</cfmDamping>
  </gazebo>
  <joint name="RWRR" type="revolute">
    <parent link="Rarm_Link4"/>
    <child  link="Rarm_Link5"/>
    <origin xyz="0 0 0" rpy="0 -0 0 "/>
    <axis   xyz="1 0 0"/>
    <limit lower="-0.820305" upper="1.22173" effort="359.184" velocity="4.865" />
    <dynamics damping="0.2" friction="0" />
  </joint>
  <transmission type="pr2_mechanism_model/SimpleTransmission" name="RWRR_trans" >
    <actuator name="RWRR_motor" />
    <joint name="RWRR" />
    <mechanicalReduction>1</mechanicalReduction>
  </transmission>
  <gazebo reference="RWRR">
    <cfmDamping>0.4</cfmDamping>
  </gazebo>
  <joint name="RWRP" type="revolute">
    <parent link="Rarm_Link5"/>
    <child  link="Rarm_Link6"/>
    <origin xyz="0 0 0" rpy="0 -0 0 "/>
    <axis   xyz="0 1 0"/>
    <limit lower="-0.733038" upper="0.733038" effort="158.714" velocity="4.817" />
    <dynamics damping="0.2" friction="0" />
  </joint>
  <transmission type="pr2_mechanism_model/SimpleTransmission" name="RWRP_trans" >
    <actuator name="RWRP_motor" />
    <joint name="RWRP" />
    <mechanicalReduction>1</mechanicalReduction>
  </transmission>
  <gazebo reference="RWRP">
    <cfmDamping>0.4</cfmDamping>
  </gazebo>
  <joint name="RHDY" type="revolute">
    <parent link="Rarm_Link6"/>
    <child  link="Rhand_Link0_Plan2"/>
    <origin xyz="0 0.017324 -0.078842" rpy="0.785398 -0 0 "/>
    <axis   xyz="0 0 1"/>
    <limit lower="-2.61799" upper="2.61799" effort="33.7995" velocity="4.803" />
    <dynamics damping="0.2" friction="0" />
  </joint>
  <transmission type="pr2_mechanism_model/SimpleTransmission" name="RHDY_trans" >
    <actuator name="RHDY_motor" />
    <joint name="RHDY" />
    <mechanicalReduction>1</mechanicalReduction>
  </transmission>
  <gazebo reference="RHDY">
    <cfmDamping>0.4</cfmDamping>
  </gazebo>
  <joint name="RIMP" type="revolute">
    <mimic joint="RTMP" multiplier="-1" offset="0" />
    <parent link="Rhand_Link0_Plan2"/>
    <child  link="Rindex_Link0"/>
    <origin xyz="0.03 -0.047 -0.114" rpy="-3.14159 -0 0 "/>
    <axis   xyz="1 0 0"/>
    <limit lower="-2.0944" upper="-0.05236" effort="38.7743" velocity="1.963" />
    <dynamics damping="0.2" friction="0" />
  </joint>
  <transmission type="pr2_mechanism_model/SimpleTransmission" name="RIMP_trans" >
    <actuator name="RIMP_motor" />
    <joint name="RIMP" />
    <mechanicalReduction>1</mechanicalReduction>
  </transmission>
  <gazebo reference="RIMP">
    <cfmDamping>0.4</cfmDamping>
  </gazebo>
  <joint name="RIPIP" type="revolute">
    <mimic joint="RTMP" multiplier="0" offset="0" />
    <parent link="Rindex_Link0"/>
    <child  link="Rindex_Link1"/>
    <origin xyz="0 -0.046 0" rpy="0 -0 0 "/>
    <axis   xyz="1 0 0"/>
    <limit lower="0" upper="1.5708" effort="38.7743" velocity="1.963" />
    <dynamics damping="0.2" friction="0" />
  </joint>
  <transmission type="pr2_mechanism_model/SimpleTransmission" name="RIPIP_trans" >
    <actuator name="RIPIP_motor" />
    <joint name="RIPIP" />
    <mechanicalReduction>1</mechanicalReduction>
  </transmission>
  <gazebo reference="RIPIP">
    <cfmDamping>0.4</cfmDamping>
  </gazebo>
  <joint name="RIDIP" type="revolute">
    <mimic joint="RTMP" multiplier="0" offset="0" />
    <parent link="Rindex_Link1"/>
    <child  link="Rindex_Link2"/>
    <origin xyz="0 -0.027 0" rpy="0 -0 0 "/>
    <axis   xyz="1 0 0"/>
    <limit lower="0" upper="2.16717" effort="38.7743" velocity="1.963" />
    <dynamics damping="0.2" friction="0" />
  </joint>
  <transmission type="pr2_mechanism_model/SimpleTransmission" name="RIDIP_trans" >
    <actuator name="RIDIP_motor" />
    <joint name="RIDIP" />
    <mechanicalReduction>1</mechanicalReduction>
  </transmission>
  <gazebo reference="RIDIP">
    <cfmDamping>0.4</cfmDamping>
  </gazebo>
  <joint name="RMMP" type="revolute">
    <mimic joint="RTMP" multiplier="-1" offset="0" />
    <parent link="Rhand_Link0_Plan2"/>
    <child  link="Rmiddle_Link0"/>
    <origin xyz="-0.03 -0.047 -0.114" rpy="-3.14159 -0 0 "/>
    <axis   xyz="1 0 0"/>
    <limit lower="-2.0944" upper="-0.05236" effort="38.7743" velocity="1.963" />
    <dynamics damping="0.2" friction="0" />
  </joint>
  <transmission type="pr2_mechanism_model/SimpleTransmission" name="RMMP_trans" >
    <actuator name="RMMP_motor" />
    <joint name="RMMP" />
    <mechanicalReduction>1</mechanicalReduction>
  </transmission>
  <gazebo reference="RMMP">
    <cfmDamping>0.4</cfmDamping>
  </gazebo>
  <joint name="RMPIP" type="revolute">
    <mimic joint="RTMP" multiplier="0" offset="0" />
    <parent link="Rmiddle_Link0"/>
    <child  link="Rmiddle_Link1"/>
    <origin xyz="0 -0.046 0" rpy="0 -0 0 "/>
    <axis   xyz="1 0 0"/>
    <limit lower="0" upper="1.5708" effort="38.7743" velocity="1.963" />
    <dynamics damping="0.2" friction="0" />
  </joint>
  <transmission type="pr2_mechanism_model/SimpleTransmission" name="RMPIP_trans" >
    <actuator name="RMPIP_motor" />
    <joint name="RMPIP" />
    <mechanicalReduction>1</mechanicalReduction>
  </transmission>
  <gazebo reference="RMPIP">
    <cfmDamping>0.4</cfmDamping>
  </gazebo>
  <joint name="RMDIP" type="revolute">
    <mimic joint="RTMP" multiplier="0" offset="0" />
    <parent link="Rmiddle_Link1"/>
    <child  link="Rmiddle_Link2"/>
    <origin xyz="0 -0.027 0" rpy="0 -0 0 "/>
    <axis   xyz="1 0 0"/>
    <limit lower="0" upper="2.16717" effort="38.7743" velocity="1.963" />
    <dynamics damping="0.2" friction="0" />
  </joint>
  <transmission type="pr2_mechanism_model/SimpleTransmission" name="RMDIP_trans" >
    <actuator name="RMDIP_motor" />
    <joint name="RMDIP" />
    <mechanicalReduction>1</mechanicalReduction>
  </transmission>
  <gazebo reference="RMDIP">
    <cfmDamping>0.4</cfmDamping>
  </gazebo>
  <joint name="RTMP" type="revolute">
    <parent link="Rhand_Link0_Plan2"/>
    <child  link="Rthumb_Link0"/>
    <origin xyz="0 0.047 -0.114" rpy="3.14159 -0 0 "/>
    <axis   xyz="1 0 0"/>
    <limit lower="0.0872665" upper="2.00713" effort="38.7742" velocity="1.923" />
    <dynamics damping="0.2" friction="0" />
  </joint>
  <transmission type="pr2_mechanism_model/SimpleTransmission" name="RTMP_trans" >
    <actuator name="RTMP_motor" />
    <joint name="RTMP" />
    <mechanicalReduction>1</mechanicalReduction>
  </transmission>
  <gazebo reference="RTMP">
    <cfmDamping>0.4</cfmDamping>
  </gazebo>
  <joint name="RTPIP" type="revolute">
    <mimic joint="RTMP" multiplier="0" offset="0" />
    <parent link="Rthumb_Link0"/>
    <child  link="Rthumb_Link1"/>
    <origin xyz="0 0.046 0" rpy="0 -0 0 "/>
    <axis   xyz="1 0 0"/>
    <limit lower="-1.5708" upper="0" effort="38.7743" velocity="1.963" />
    <dynamics damping="0.2" friction="0" />
  </joint>
  <transmission type="pr2_mechanism_model/SimpleTransmission" name="RTPIP_trans" >
    <actuator name="RTPIP_motor" />
    <joint name="RTPIP" />
    <mechanicalReduction>1</mechanicalReduction>
  </transmission>
  <gazebo reference="RTPIP">
    <cfmDamping>0.4</cfmDamping>
  </gazebo>
  <joint name="RTDIP" type="revolute">
    <mimic joint="RTMP" multiplier="0" offset="0" />
    <parent link="Rthumb_Link1"/>
    <child  link="Rthumb_Link2"/>
    <origin xyz="0 0.027 0" rpy="0 -0 0 "/>
    <axis   xyz="1 0 0"/>
    <limit lower="-2.16717" upper="0" effort="38.7743" velocity="1.963" />
    <dynamics damping="0.2" friction="0" />
  </joint>
  <transmission type="pr2_mechanism_model/SimpleTransmission" name="RTDIP_trans" >
    <actuator name="RTDIP_motor" />
    <joint name="RTDIP" />
    <mechanicalReduction>1</mechanicalReduction>
  </transmission>
  <gazebo reference="RTDIP">
    <cfmDamping>0.4</cfmDamping>
  </gazebo>
</robot>
